Workbook

Sheet Tables
B2: The lock password is "password" | F2: Still available for ascii chars: o, =, |
B4: orig | C4: (X) | E4: orig | F4: (Y) | H4: orig | I4: (Z) | K4: orig | L4: (T-reflection) | N4: orig | O4: (H-reflection) | Q4: orig | R4: (S-reflection)
B5: R | C5: R | E5: R | F5: F | H5: R | I5: D | K5: R | L5: L' | N5: R | O5: R' | Q5: R | R5: R'
B6: r | C6: r | E6: r | F6: f | H6: r | I6: d | K6: r | L6: l' | N6: r | O6: r' | Q6: r | R6: r'
B7: T | C7: T | E7: T | F7: S | H7: T | I7: H' | K7: T | L7: T | N7: T | O7: T' | Q7: T | R7: T'
B8: l | C8: l | E8: l | F8: b | H8: l | I8: u | K8: l | L8: r' | N8: l | O8: l' | Q8: l | R8: l'
B9: L | C9: L | E9: L | F9: B | H9: L | I9: U | K9: L | L9: R' | N9: L | O9: L' | Q9: L | R9: L'
B10: X | C10: X | E10: X | F10: Z | H10: X | I10: Y' | K10: X | L10: X | N10: X | O10: X' | Q10: X | R10: X'
B11: R' | C11: R' | E11: R' | F11: F' | H11: R' | I11: D' | K11: R' | L11: L | N11: R' | O11: R | Q11: R' | R11: R
B12: r' | C12: r' | E12: r' | F12: f' | H12: r' | I12: d' | K12: r' | L12: l | N12: r' | O12: r | Q12: r' | R12: r
B13: T' | C13: T' | E13: T' | F13: S' | H13: T' | I13: H | K13: T' | L13: T' | N13: T' | O13: T | Q13: T' | R13: T
B14: l' | C14: l' | E14: l' | F14: b' | H14: l' | I14: u' | K14: l' | L14: r | N14: l' | O14: l | Q14: l' | R14: l
B15: L' | C15: L' | E15: L' | F15: B' | H15: L' | I15: U' | K15: L' | L15: R | N15: L' | O15: L | Q15: L' | R15: L
... B58: Y2 | C58: Z2 | E58: Y2 | F58: Y2 | H58: Y2 | I58: X2 | K58: Y2 | L58: Y2 | N58: Y2 | O58: Y2 | Q58: Y2 | R58: Y2

Sheet Other Tables
B3: Both face turns whose complement has a given rotation | E3: - | F3: SeekCodes | L3: All Coros (Core Rotations) | S3: DO6 - multiple methods of identification | Y3: Mod 4 tracker
B4: Rotation | C4: Opposite Primary | D4: Opposite Secondary | F4: Face Turn Sought | G4: char | H4: opp Rotation | I4: SeekCode | L4: Coro | M4: Type | N4: Group | O4: thumb pivot | P4: U-F center | Q4: 180 swap | S4: Types | T4: Groups | U4: Thumbs | V4: U-F centers | W4: 180 swaps | Y4: X | Z4: Y | AA4: Z | AB4: RotationNum | AC4: CompRotationNum
B5: X | C5: R' | D5: L | F5: R | G5: {=_xlfn.XLOOKUP(TRUE, EXACT(Table12[[#This Row],[Face Turn Sought]], Table9[orig]), Table9[char])} -> R | H5: X' | I5: 2 | L5: X2 Y | M5: X2 Y | N5: Group 1 | O5: FR | P5: yellow-blue | Q5: PAPER | S5: X2 Y | T5: Group 1 | U5: FR | V5: yellow-blue | W5: PAPER | Y5: MyAlg | Z5: MyAlg | AA5: MyAlg | AB5: 0 | AC5: =MOD(4-Table14[[#This Row],[RotationNum]],4) -> 0
F6: r | G6: {=_xlfn.XLOOKUP(TRUE, EXACT(Table12[[#This Row],[Face Turn Sought]], Table9[orig]), Table9[char])} -> r | H6: X' | L6: Y' X2 | M6: X2 Y | N6: Group 1 | O6: FR | P6: yellow-blue | Q6: PAPER | S6: X2 Y' | T6: Group 2 | U6: FL | V6: yellow-green | W6: PAPER | Y6: X | Z6: Y | AA6: Z | AB6: 1 | AC6: =MOD(4-Table14[[#This Row],[RotationNum]],4) -> 3
L7: Z2 Y' | M7: X2 Y | N7: Group 1 | O7: FR | P7: yellow-blue | Q7: PAPER | S7: Y2 Z | T7: Group 3 | U7: UR | V7: blue-orange | W7: FIRE | Y7: R | AB7: 1 | AC7: =MOD(4-Table14[[#This Row],[RotationNum]],4) -> 3
F8: l | G8: {=_xlfn.XLOOKUP(TRUE, EXACT(Table12[[#This Row],[Face Turn Sought]], Table9[orig]), Table9[char])} -> l | H8: X | L8: Y Z2 | M8: X2 Y | N8: Group 1 | O8: FR | P8: yellow-blue | Q8: PAPER | S8: Y2 Z' | T8: Group 4 | U8: UL | V8: green-orange | W8: FIRE | Y8: r | AB8: 1 | AC8: =MOD(4-Table14[[#This Row],[RotationNum]],4) -> 3
F9: L | G9: {=_xlfn.XLOOKUP(TRUE, EXACT(Table12[[#This Row],[Face Turn Sought]], Table9[orig]), Table9[char])} -> L | H9: X | I9: 1 | L9: X X Y | M9: X2 Y | N9: Group 1 | O9: FR | P9: yellow-blue | Q9: PAPER | S9: Z2 X | T9: Group 5 | U9: UF | V9: red-white | W9: WATER | Y9: T | AB9: 1 | AC9: =MOD(4-Table14[[#This Row],[RotationNum]],4) -> 3
L10: X' X' Y | M10: X2 Y | N10: Group 1 | O10: FR | P10: yellow-blue | Q10: PAPER | S10: Z2 X' | T10: Group 6 | U10: UB | V10: orange-yellow | W10: WATER | Y10: M' | AB10: 1 | AC10: =MOD(4-Table14[[#This Row],[RotationNum]],4) -> 3
B11: X' | C11: R | D11: L' | F11: R' | G11: {=_xlfn.XLOOKUP(TRUE, EXACT(Table12[[#This Row],[Face Turn Sought]], Table9[orig]), Table9[char])} -> A | H11: X | I11: 1 | L11: Y' X X | M11: X2 Y | N11: Group 1 | O11: FR | P11: yellow-blue | Q11: PAPER | Y11: l' | AB11: 1 | AC11: =MOD(4-Table14[[#This Row],[RotationNum]],4) -> 3
F12: r' | G12: {=_xlfn.XLOOKUP(TRUE, EXACT(Table12[[#This Row],[Face Turn Sought]], Table9[orig]), Table9[char])} -> a | H12: X | L12: Y' X' X' | M12: X2 Y | N12: Group 1 | O12: FR | P12: yellow-blue | Q12: PAPER | Y12: L' | AB12: 1 | AC12: =MOD(4-Table14[[#This Row],[RotationNum]],4) -> 3
L13: Z Z Y' | M13: X2 Y | N13: Group 1 | O13: FR | P13: yellow-blue | Q13: PAPER | Y13: X2 | Z13: Y2 | AA13: Z2 | AB13: 2 | AC13: =MOD(4-Table14[[#This Row],[RotationNum]],4) -> 2
F14: l' | G14: {=_xlfn.XLOOKUP(TRUE, EXACT(Table12[[#This Row],[Face Turn Sought]], Table9[orig]), Table9[char])} -> g | H14: X' | L14: Z' Z' Y' | M14: X2 Y | N14: Group 1 | O14: FR | P14: yellow-blue | Q14: PAPER | Y14: R2 | AB14: 2 | AC14: =MOD(4-Table14[[#This Row],[RotationNum]],4) -> 2
F15: L' | G15: {=_xlfn.XLOOKUP(TRUE, EXACT(Table12[[#This Row],[Face Turn Sought]], Table9[orig]), Table9[char])} -> G | H15: X' | I15: 2 | L15: Y Z Z | M15: X2 Y | N15: Group 1 | O15: FR | P15: yellow-blue | Q15: PAPER | Y15: r2 | AB15: 2 | AC15: =MOD(4-Table14[[#This Row],[RotationNum]],4) -> 2
L16: Y Z' Z' | M16: X2 Y | N16: Group 1 | O16: FR | P16: yellow-blue | Q16: PAPER | Y16: T2 | AB16: 2 | AC16: =MOD(4-Table14[[#This Row],[RotationNum]],4) -> 2
B17: X2 | C17: R2 | D17: L2 | F17: R2 | G17: {=_xlfn.XLOOKUP(TRUE, EXACT(Table12[[#This Row],[Face Turn Sought]], Table9[orig]), Table9[char])} -> J | H17: X2 | I17: 3 | L17: X Z X | M17: X2 Y | N17: Group 1 | O17: FR | P17: yellow-blue | Q17: PAPER | Y17: M2 | AB17: 2 | AC17: =MOD(4-Table14[[#This Row],[RotationNum]],4) -> 2
F18: r2 | G18: {=_xlfn.XLOOKUP(TRUE, EXACT(Table12[[#This Row],[Face Turn Sought]], Table9[orig]), Table9[char])} -> j | H18: X2 | L18: X' Z' X' | M18: X2 Y | N18: Group 1 | O18: FR | P18: yellow-blue | Q18: PAPER | Y18: l2 | AB18: 2 | AC18: =MOD(4-Table14[[#This Row],[RotationNum]],4) -> 2
L19: Z X Z | M19: X2 Y | N19: Group 1 | O19: FR | P19: yellow-blue | Q19: PAPER | Y19: L2 | AB19: 2 | AC19: =MOD(4-Table14[[#This Row],[RotationNum]],4) -> 2
F20: l2 | G20: {=_xlfn.XLOOKUP(TRUE, EXACT(Table12[[#This Row],[Face Turn Sought]], Table9[orig]), Table9[char])} -> n | H20: X2 | L20: Z' X' Z' | M20: X2 Y | N20: Group 1 | O20: FR | P20: yellow-blue | Q20: PAPER | Y20: X' | Z20: Y' | AA20: Z' | AB20: 3 | AC20: =MOD(4-Table14[[#This Row],[RotationNum]],4) -> 1
F21: L2 | G21: {=_xlfn.XLOOKUP(TRUE, EXACT(Table12[[#This Row],[Face Turn Sought]], Table9[orig]), Table9[char])} -> N | H21: X2 | I21: 3 | L21: X Y Z | M21: X2 Y | N21: Group 1 | O21: FR | P21: yellow-blue | Q21: PAPER | Y21: R' | AB21: 3 | AC21: =MOD(4-Table14[[#This Row],[RotationNum]],4) -> 1
L22: Z' Y' X' | M22: X2 Y | N22: Group 1 | O22: FR | P22: yellow-blue | Q22: PAPER | Y22: r' | AB22: 3 | AC22: =MOD(4-Table14[[#This Row],[RotationNum]],4) -> 1
B23: Z | C23: F' | D23: B | F23: F | G23: {=_xlfn.XLOOKUP(TRUE, EXACT(Table12[[#This Row],[Face Turn Sought]], Table9[orig]), Table9[char])} -> F | H23: Z' | I23: 8 | L23: X' Y Z' | M23: X2 Y | N23: Group 1 | O23: FR | P23: yellow-blue | Q23: PAPER | Y23: T' | AB23: 3 | AC23: =MOD(4-Table14[[#This Row],[RotationNum]],4) -> 1
L24: Z Y' X | M24: X2 Y | N24: Group 1 | O24: FR | P24: yellow-blue | Q24: PAPER | Y24: M | AB24: 3 | AC24: =MOD(4-Table14[[#This Row],[RotationNum]],4) -> 1
L25: X2 Y' | M25: X2 Y' | N25: Group 2 | O25: FL | P25: yellow-green | Q25: PAPER | Y25: l | AB25: 3 | AC25: =MOD(4-Table14[[#This Row],[RotationNum]],4) -> 1
L26: Y X2 | M26: X2 Y' | N26: Group 2 | O26: FL | P26: yellow-green | Q26: PAPER | Y26: L | AB26: 3 | AC26: =MOD(4-Table14[[#This Row],[RotationNum]],4) -> 1
F27: B | G27: {=_xlfn.XLOOKUP(TRUE, EXACT(Table12[[#This Row],[Face Turn Sought]], Table9[orig]), Table9[char])} -> B | H27: Z | I27: 7 | L27: Z2 Y | M27: X2 Y' | N27: Group 2 | O27: FL | P27: yellow-green | Q27: PAPER
L28: Y' Z2 | M28: X2 Y' | N28: Group 2 | O28: FL | P28: yellow-green | Q28: PAPER
B29: Z' | C29: F | D29: B' | F29: F' | G29: {=_xlfn.XLOOKUP(TRUE, EXACT(Table12[[#This Row],[Face Turn Sought]], Table9[orig]), Table9[char])} -> Q | H29: Z | I29: 7 | L29: X X Y' | M29: X2 Y' | N29: Group 2 | O29: FL | P29: yellow-green | Q29: PAPER
L30: X' X' Y' | M30: X2 Y' | N30: Group 2 | O30: FL | P30: yellow-green | Q30: PAPER
L31: Y X X | M31: X2 Y' | N31: Group 2 | O31: FL | P31: yellow-green | Q31: PAPER
L32: Y X' X' | M32: X2 Y' | N32: Group 2 | O32: FL | P32: yellow-green | Q32: PAPER
F33: B' | G33: {=_xlfn.XLOOKUP(TRUE, EXACT(Table12[[#This Row],[Face Turn Sought]], Table9[orig]), Table9[char])} -> @ | H33: Z' | I33: 8 | L33: Z Z Y | M33: X2 Y' | N33: Group 2 | O33: FL | P33: yellow-green | Q33: PAPER
L34: Z' Z' Y | M34: X2 Y' | N34: Group 2 | O34: FL | P34: yellow-green | Q34: PAPER
B35: Z2 | C35: F2 | D35: B2 | F35: F2 | G35: {=_xlfn.XLOOKUP(TRUE, EXACT(Table12[[#This Row],[Face Turn Sought]], Table9[orig]), Table9[char])} -> $ | H35: Z2 | I35: 9 | L35: Y' Z Z | M35: X2 Y' | N35: Group 2 | O35: FL | P35: yellow-green | Q35: PAPER
L36: Y' Z' Z' | M36: X2 Y' | N36: Group 2 | O36: FL | P36: yellow-green | Q36: PAPER
L37: X Z' X | M37: X2 Y' | N37: Group 2 | O37: FL | P37: yellow-green | Q37: PAPER
L38: X' Z X' | M38: X2 Y' | N38: Group 2 | O38: FL | P38: yellow-green | Q38: PAPER
F39: B2 | G39: {=_xlfn.XLOOKUP(TRUE, EXACT(Table12[[#This Row],[Face Turn Sought]], Table9[orig]), Table9[char])} -> ` | H39: Z2 | I39: 9 | L39: Z X' Z | M39: X2 Y' | N39: Group 2 | O39: FL | P39: yellow-green | Q39: PAPER
L40: Z' X Z' | M40: X2 Y' | N40: Group 2 | O40: FL | P40: yellow-green | Q40: PAPER
B41: Y | C41: U' | D41: D | F41: U | G41: {=_xlfn.XLOOKUP(TRUE, EXACT(Table12[[#This Row],[Face Turn Sought]], Table9[orig]), Table9[char])} -> U | H41: Y' | I41: 5 | L41: X Y' Z' | M41: X2 Y' | N41: Group 2 | O41: FL | P41: yellow-green | Q41: PAPER
L42: Z Y X' | M42: X2 Y' | N42: Group 2 | O42: FL | P42: yellow-green | Q42: PAPER
...

Sheet table_1
A1: orig | B1: char | C1: code | D1: inverse | E1: inv char | F1: inv code | G1: Complement | H1: CompChar | I1: Rotation Direction | J1: orig + <space>
A2: R | B2: R | C2: =CODE(Table9[[#This Row],[char]]) -> 82 | D2: R' | E2: {=_xlfn.XLOOKUP(TRUE, EXACT(Table9[[#This Row],[inverse]], Table9[orig]), Table9[char])} -> A | F2: =CODE(Table9[[#This Row],[inv char]]) -> 65 | G2: l | H2: {=_xlfn.XLOOKUP(TRUE, EXACT(Table9[[#This Row],[Complement]], Table9[orig]), Table9[char])} -> l | I2: X | J2: =Table9[[#This Row],[orig]] & " " -> R
A3: r | B3: r | C3: =CODE(Table9[[#This Row],[char]]) -> 114 | D3: r' | E3: {=_xlfn.XLOOKUP(TRUE, EXACT(Table9[[#This Row],[inverse]], Table9[orig]), Table9[char])} -> a | F3: =CODE(Table9[[#This Row],[inv char]]) -> 97 | G3: L | H3: {=_xlfn.XLOOKUP(TRUE, EXACT(Table9[[#This Row],[Complement]], Table9[orig]), Table9[char])} -> L | I3: X | J3: =Table9[[#This Row],[orig]] & " " -> r
A4: T | B4: T | C4: =CODE(Table9[[#This Row],[char]]) -> 84 | D4: T' | E4: {=_xlfn.XLOOKUP(TRUE, EXACT(Table9[[#This Row],[inverse]], Table9[orig]), Table9[char])} -> C | F4: =CODE(Table9[[#This Row],[inv char]]) -> 67 | G4: R'L | H4: {=_xlfn.CONCAT(_xlfn.XLOOKUP(TRUE, EXACT(A8, Table9[orig]), Table9[char]), _xlfn.XLOOKUP(TRUE, EXACT(A6, Table9[orig]), Table9[char]))} -> AL | I4: X | J4: =Table9[[#This Row],[orig]] & " " -> T
A5: l | B5: l | C5: =CODE(Table9[[#This Row],[char]]) -> 108 | D5: l' | E5: {=_xlfn.XLOOKUP(TRUE, EXACT(Table9[[#This Row],[inverse]], Table9[orig]), Table9[char])} -> g | F5: =CODE(Table9[[#This Row],[inv char]]) -> 103 | G5: R | H5: {=_xlfn.XLOOKUP(TRUE, EXACT(Table9[[#This Row],[Complement]], Table9[orig]), Table9[char])} -> R | I5: X' | J5: =Table9[[#This Row],[orig]] & " " -> l
A6: L | B6: L | C6: =CODE(Table9[[#This Row],[char]]) -> 76 | D6: L' | E6: {=_xlfn.XLOOKUP(TRUE, EXACT(Table9[[#This Row],[inverse]], Table9[orig]), Table9[char])} -> G | F6: =CODE(Table9[[#This Row],[inv char]]) -> 71 | G6: r | H6: {=_xlfn.XLOOKUP(TRUE, EXACT(Table9[[#This Row],[Complement]], Table9[orig]), Table9[char])} -> r | I6: X' | J6: =Table9[[#This Row],[orig]] & " " -> L
A7: X | B7: X | C7: =CODE(Table9[[#This Row],[char]]) -> 88 | D7: X' | E7: {=_xlfn.XLOOKUP(TRUE, EXACT(Table9[[#This Row],[inverse]], Table9[orig]), Table9[char])} -> ! | F7: =CODE(Table9[[#This Row],[inv char]]) -> 33 | G7: 0 | H7: 0 | I7: X | J7: =Table9[[#This Row],[orig]] & " " -> X
A8: R' | B8: A | C8: =CODE(Table9[[#This Row],[char]]) -> 65 | D8: R | E8: {=_xlfn.XLOOKUP(TRUE, EXACT(Table9[[#This Row],[inverse]], Table9[orig]), Table9[char])} -> R | F8: =CODE(Table9[[#This Row],[inv char]]) -> 82 | G8: l' | H8: {=_xlfn.XLOOKUP(TRUE, EXACT(Table9[[#This Row],[Complement]], Table9[orig]), Table9[char])} -> g | I8: X' | J8: =Table9[[#This Row],[orig]] & " " -> R'
A9: r' | B9: a | C9: =CODE(Table9[[#This Row],[char]]) -> 97 | D9: r | E9: {=_xlfn.XLOOKUP(TRUE, EXACT(Table9[[#This Row],[inverse]], Table9[orig]), Table9[char])} -> r | F9: =CODE(Table9[[#This Row],[inv char]]) -> 114 | G9: L' | H9: {=_xlfn.XLOOKUP(TRUE, EXACT(Table9[[#This Row],[Complement]], Table9[orig]), Table9[char])} -> G | I9: X' | J9: =Table9[[#This Row],[orig]] & " " -> r'
A10: T' | B10: C | C10: =CODE(Table9[[#This Row],[char]]) -> 67 | D10: T | E10: {=_xlfn.XLOOKUP(TRUE, EXACT(Table9[[#This Row],[inverse]], Table9[orig]), Table9[char])} -> T | F10: =CODE(Table9[[#This Row],[inv char]]) -> 84 | G10: RL' | H10: {=_xlfn.CONCAT(_xlfn.XLOOKUP(TRUE, EXACT(A2, Table9[orig]), Table9[char]), _xlfn.XLOOKUP(TRUE, EXACT(A12, Table9[orig]), Table9[char]))} -> RG | I10: X' | J10: =Table9[[#This Row],[orig]] & " " -> T'
A11: l' | B11: g | C11: =CODE(Table9[[#This Row],[char]]) -> 103 | D11: l | E11: {=_xlfn.XLOOKUP(TRUE, EXACT(Table9[[#This Row],[inverse]], Table9[orig]), Table9[char])} -> l | F11: =CODE(Table9[[#This Row],[inv char]]) -> 108 | G11: R' | H11: {=_xlfn.XLOOKUP(TRUE, EXACT(Table9[[#This Row],[Complement]], Table9[orig]), Table9[char])} -> A | I11: X | J11: =Table9[[#This Row],[orig]] & " " -> l'
A12: L' | B12: G | C12: =CODE(Table9[[#This Row],[char]]) -> 71 | D12: L | E12: {=_xlfn.XLOOKUP(TRUE, EXACT(Table9[[#This Row],[inverse]], Table9[orig]), Table9[char])} -> L | F12: =CODE(Table9[[#This Row],[inv char]]) -> 76 | G12: r' | H12: {=_xlfn.XLOOKUP(TRUE, EXACT(Table9[[#This Row],[Complement]], Table9[orig]), Table9[char])} -> a | I12: X | J12: =Table9[[#This Row],[orig]] & " " -> L'
A13: X' | B13: ! | C13: =CODE(Table9[[#This Row],[char]]) -> 33 | D13: X | E13: {=_xlfn.XLOOKUP(TRUE, EXACT(Table9[[#This Row],[inverse]], Table9[orig]), Table9[char])} -> X | F13: =CODE(Table9[[#This Row],[inv char]]) -> 88 | G13: 0 | H13: 0 | I13: X' | J13: =Table9[[#This Row],[orig]] & " " -> X'
A14: R2 | B14: J | C14: =CODE(Table9[[#This Row],[char]]) -> 74 | D14: R2 | E14: {=_xlfn.XLOOKUP(TRUE, EXACT(Table9[[#This Row],[inverse]], Table9[orig]), Table9[char])} -> J | F14: =CODE(Table9[[#This Row],[inv char]]) -> 74 | G14: l2 | H14: {=_xlfn.XLOOKUP(TRUE, EXACT(Table9[[#This Row],[Complement]], Table9[orig]), Table9[char])} -> n | I14: X2 | J14: =Table9[[#This Row],[orig]] & " " -> R2
A15: r2 | B15: j | C15: =CODE(Table9[[#This Row],[char]]) -> 106 | D15: r2 | E15: {=_xlfn.XLOOKUP(TRUE, EXACT(Table9[[#This Row],[inverse]], Table9[orig]), Table9[char])} -> j | F15: =CODE(Table9[[#This Row],[inv char]]) -> 106 | G15: L2 | H15: {=_xlfn.XLOOKUP(TRUE, EXACT(Table9[[#This Row],[Complement]], Table9[orig]), Table9[char])} -> N | I15: X2 | J15: =Table9[[#This Row],[orig]] & " " -> r2
A16: T2 | B16: K | C16: =CODE(Table9[[#This Row],[char]]) -> 75 | D16: T2 | E16: {=_xlfn.XLOOKUP(TRUE, EXACT(Table9[[#This Row],[inverse]], Table9[orig]), Table9[char])} -> K | F16: =CODE(Table9[[#This Row],[inv char]]) -> 75 | G16: R2L2 | H16: {=_xlfn.CONCAT(_xlfn.XLOOKUP(TRUE, EXACT(A14, Table9[orig]), Table9[char]), _xlfn.XLOOKUP(TRUE, EXACT(A18, Table9[orig]), Table9[char]))} -> JN | I16: X2 | J16: =Table9[[#This Row],[orig]] & " " -> T2
A17: l2 | B17: n | C17: =CODE(Table9[[#This Row],[char]]) -> 110 | D17: l2 | E17: {=_xlfn.XLOOKUP(TRUE, EXACT(Table9[[#This Row],[inverse]], Table9[orig]), Table9[char])} -> n | F17: =CODE(Table9[[#This Row],[inv char]]) -> 110 | G17: R2 | H17: {=_xlfn.XLOOKUP(TRUE, EXACT(Table9[[#This Row],[Complement]], Table9[orig]), Table9[char])} -> J | I17: X2 | J17: =Table9[[#This Row],[orig]] & " " -> l2
A18: L2 | B18: N | C18: =CODE(Table9[[#This Row],[char]]) -> 78 | D18: L2 | E18: {=_xlfn.XLOOKUP(TRUE, EXACT(Table9[[#This Row],[inverse]], Table9[orig]), Table9[char])} -> N | F18: =CODE(Table9[[#This Row],[inv char]]) -> 78 | G18: r2 | H18: {=_xlfn.XLOOKUP(TRUE, EXACT(Table9[[#This Row],[Complement]], Table9[orig]), Table9[char])} -> j | I18: X2 | J18: =Table9[[#This Row],[orig]] & " " -> L2
A19: X2 | B19: P | C19: =CODE(Table9[[#This Row],[char]]) -> 80 | D19: X2 | E19: {=_xlfn.XLOOKUP(TRUE, EXACT(Table9[[#This Row],[inverse]], Table9[orig]), Table9[char])} -> P | F19: =CODE(Table9[[#This Row],[inv char]]) -> 80 | G19: 0 | H19: 0 | I19: X2 | J19: =Table9[[#This Row],[orig]] & " " -> X2
A20: F | B20: F | C20: =CODE(Table9[[#This Row],[char]]) -> 70 | D20: F' | E20: {=_xlfn.XLOOKUP(TRUE, EXACT(Table9[[#This Row],[inverse]], Table9[orig]), Table9[char])} -> Q | F20: =CODE(Table9[[#This Row],[inv char]]) -> 81 | G20: b | H20: {=_xlfn.XLOOKUP(TRUE, EXACT(Table9[[#This Row],[Complement]], Table9[orig]), Table9[char])} -> b | I20: Z | J20: =Table9[[#This Row],[orig]] & " " -> F
A21: f | B21: f | C21: =CODE(Table9[[#This Row],[char]]) -> 102 | D21: f' | E21: {=_xlfn.XLOOKUP(TRUE, EXACT(Table9[[#This Row],[inverse]], Table9[orig]), Table9[char])} -> q | F21: =CODE(Table9[[#This Row],[inv char]]) -> 113 | G21: B | H21: {=_xlfn.XLOOKUP(TRUE, EXACT(Table9[[#This Row],[Complement]], Table9[orig]), Table9[char])} -> B | I21: Z | J21: =Table9[[#This Row],[orig]] & " " -> f
A22: S | B22: S | C22: =CODE(Table9[[#This Row],[char]]) -> 83 | D22: S' | E22: {=_xlfn.XLOOKUP(TRUE, EXACT(Table9[[#This Row],[inverse]], Table9[orig]), Table9[char])} -> V | F22: =CODE(Table9[[#This Row],[inv char]]) -> 86 | G22: F'B | H22: {=_xlfn.CONCAT(_xlfn.XLOOKUP(TRUE, EXACT(A26, Table9[orig]), Table9[char]), _xlfn.XLOOKUP(TRUE, EXACT(A24, Table9[orig]), Table9[char]))} -> QB | I22: Z | J22: =Table9[[#This Row],[orig]] & " " -> S
A23: b | B23: b | C23: =CODE(Table9[[#This Row],[char]]) -> 98 | D23: b' | E23: {=_xlfn.XLOOKUP(TRUE, EXACT(Table9[[#This Row],[inverse]], Table9[orig]), Table9[char])} -> & | F23: =CODE(Table9[[#This Row],[inv char]]) -> 38 | G23: F | H23: {=_xlfn.XLOOKUP(TRUE, EXACT(Table9[[#This Row],[Complement]], Table9[orig]), Table9[char])} -> F | I23: Z' | J23: =Table9[[#This Row],[orig]] & " " -> b
A24: B | B24: B | C24: =CODE(Table9[[#This Row],[char]]) -> 66 | D24: B' | E24: {=_xlfn.XLOOKUP(TRUE, EXACT(Table9[[#This Row],[inverse]], Table9[orig]), Table9[char])} -> @ | F24: =CODE(Table9[[#This Row],[inv char]]) -> 64 | G24: f | H24: {=_xlfn.XLOOKUP(TRUE, EXACT(Table9[[#This Row],[Complement]], Table9[orig]), Table9[char])} -> f | I24: Z' | J24: =Table9[[#This Row],[orig]] & " " -> B
A25: Z | B25: Z | C25: =CODE(Table9[[#This Row],[char]]) -> 90 | D25: Z' | E25: {=_xlfn.XLOOKUP(TRUE, EXACT(Table9[[#This Row],[inverse]], Table9[orig]), Table9[char])} -> # | F25: =CODE(Table9[[#This Row],[inv char]]) -> 35 | G25: 0 | H25: 0 | I25: Z | J25: =Table9[[#This Row],[orig]] & " " -> Z
A26: F' | B26: Q | C26: =CODE(Table9[[#This Row],[char]]) -> 81 | D26: F | E26: {=_xlfn.XLOOKUP(TRUE, EXACT(Table9[[#This Row],[inverse]], Table9[orig]), Table9[char])} -> F | F26: =CODE(Table9[[#This Row],[inv char]]) -> 70 | G26: b' | H26: {=_xlfn.XLOOKUP(TRUE, EXACT(Table9[[#This Row],[Complement]], Table9[orig]), Table9[char])} -> & | I26: Z' | J26: =Table9[[#This Row],[orig]] & " " -> F'
A27: f' | B27: q | C27: =CODE(Table9[[#This Row],[char]]) -> 113 | D27: f | E27: {=_xlfn.XLOOKUP(TRUE, EXACT(Table9[[#This Row],[inverse]], Table9[orig]), Table9[char])} -> f | F27: =CODE(Table9[[#This Row],[inv char]]) -> 102 | G27: B' | H27: {=_xlfn.XLOOKUP(TRUE, EXACT(Table9[[#This Row],[Complement]], Table9[orig]), Table9[char])} -> @ | I27: Z' | J27: =Table9[[#This Row],[orig]] & " " -> f'
A28: S' | B28: V | C28: =CODE(Table9[[#This Row],[char]]) -> 86 | D28: S | E28: {=_xlfn.XLOOKUP(TRUE, EXACT(Table9[[#This Row],[inverse]], Table9[orig]), Table9[char])} -> S | F28: =CODE(Table9[[#This Row],[inv char]]) -> 83 | G28: FB' | H28: {=_xlfn.CONCAT(_xlfn.XLOOKUP(TRUE, EXACT(A20, Table9[orig]), Table9[char]), _xlfn.XLOOKUP(TRUE, EXACT(A30, Table9[orig]), Table9[char]))} -> F@ | I28: Z' | J28: =Table9[[#This Row],[orig]] & " " -> S'
A29: b' | B29: & | C29: =CODE(Table9[[#This Row],[char]]) -> 38 | D29: b | E29: {=_xlfn.XLOOKUP(TRUE, EXACT(Table9[[#This Row],[inverse]], Table9[orig]), Table9[char])} -> b | F29: =CODE(Table9[[#This Row],[inv char]]) -> 98 | G29: F' | H29: {=_xlfn.XLOOKUP(TRUE, EXACT(Table9[[#This Row],[Complement]], Table9[orig]), Table9[char])} -> Q | I29: Z | J29: =Table9[[#This Row],[orig]] & " " -> b'
A30: B' | B30: @ | C30: =CODE(Table9[[#This Row],[char]]) -> 64 | D30: B | E30: {=_xlfn.XLOOKUP(TRUE, EXACT(Table9[[#This Row],[inverse]], Table9[orig]), Table9[char])} -> B | F30: =CODE(Table9[[#This Row],[inv char]]) -> 66 | G30: f' | H30: {=_xlfn.XLOOKUP(TRUE, EXACT(Table9[[#This Row],[Complement]], Table9[orig]), Table9[char])} -> q | I30: Z | J30: =Table9[[#This Row],[orig]] & " " -> B'
A31: Z' | B31: # | C31: =CODE(Table9[[#This Row],[char]]) -> 35 | D31: Z | E31: {=_xlfn.XLOOKUP(TRUE, EXACT(Table9[[#This Row],[inverse]], Table9[orig]), Table9[char])} -> Z | F31: =CODE(Table9[[#This Row],[inv char]]) -> 90 | G31: 0 | H31: 0 | I31: Z' | J31: =Table9[[#This Row],[orig]] & " " -> Z'
A32: F2 | B32: $ | C32: =CODE(Table9[[#This Row],[char]]) -> 36 | D32: F2 | E32: {=_xlfn.XLOOKUP(TRUE, EXACT(Table9[[#This Row],[inverse]], Table9[orig]), Table9[char])} -> $ | F32: =CODE(Table9[[#This Row],[inv char]]) -> 36 | G32: b2 | H32: {=_xlfn.XLOOKUP(TRUE, EXACT(Table9[[#This Row],[Complement]], Table9[orig]), Table9[char])} -> ~ | I32: Z2 | J32: =Table9[[#This Row],[orig]] & " " -> F2
A33: f2 | B33: ? | C33: =CODE(Table9[[#This Row],[char]]) -> 63 | D33: f2 | E33: {=_xlfn.XLOOKUP(TRUE, EXACT(Table9[[#This Row],[inverse]], Table9[orig]), Table9[char])} -> ? | F33: =CODE(Table9[[#This Row],[inv char]]) -> 63 | G33: B2 | H33: {=_xlfn.XLOOKUP(TRUE, EXACT(Table9[[#This Row],[Complement]], Table9[orig]), Table9[char])} -> ` | I33: Z2 | J33: =Table9[[#This Row],[orig]] & " " -> f2
A34: S2 | B34: ^ | C34: =CODE(Table9[[#This Row],[char]]) -> 94 | D34: S2 | E34: {=_xlfn.XLOOKUP(TRUE, EXACT(Table9[[#This Row],[inverse]], Table9[orig]), Table9[char])} -> ^ | F34: =CODE(Table9[[#This Row],[inv char]]) -> 94 | G34: F2B2 | H34: {=_xlfn.CONCAT(_xlfn.XLOOKUP(TRUE, EXACT(A32, Table9[orig]), Table9[char]), _xlfn.XLOOKUP(TRUE, EXACT(A36, Table9[orig]), Table9[char]))} -> $` | I34: Z2 | J34: =Table9[[#This Row],[orig]] & " " -> S2
A35: b2 | B35: ~ | C35: =CODE(Table9[[#This Row],[char]]) -> 126 | D35: b2 | E35: {=_xlfn.XLOOKUP(TRUE, EXACT(Table9[[#This Row],[inverse]], Table9[orig]), Table9[char])} -> ~ | F35: =CODE(Table9[[#This Row],[inv char]]) -> 126 | G35: F2 | H35: {=_xlfn.XLOOKUP(TRUE, EXACT(Table9[[#This Row],[Complement]], Table9[orig]), Table9[char])} -> $ | I35: Z2 | J35: =Table9[[#This Row],[orig]] & " " -> b2
A36: B2 | B36: ` | C36: =CODE(Table9[[#This Row],[char]]) -> 96 | D36: B2 | E36: {=_xlfn.XLOOKUP(TRUE, EXACT(Table9[[#This Row],[inverse]], Table9[orig]), Table9[char])} -> ` | F36: =CODE(Table9[[#This Row],[inv char]]) -> 96 | G36: f2 | H36: {=_xlfn.XLOOKUP(TRUE, EXACT(Table9[[#This Row],[Complement]], Table9[orig]), Table9[char])} -> ? | I36: Z2 | J36: =Table9[[#This Row],[orig]] & " " -> B2
A37: Z2 | B37: = | C37: =CODE(Table9[[#This Row],[char]]) -> 61 | D37: Z2 | E37: {=_xlfn.XLOOKUP(TRUE, EXACT(Table9[[#This Row],[inverse]], Table9[orig]), Table9[char])} -> = | F37: =CODE(Table9[[#This Row],[inv char]]) -> 61 | G37: 0 | H37: 0 | I37: Z2 | J37: =Table9[[#This Row],[orig]] & " " -> Z2
A38: U | B38: U | C38: =CODE(Table9[[#This Row],[char]]) -> 85 | D38: U' | E38: {=_xlfn.XLOOKUP(TRUE, EXACT(Table9[[#This Row],[inverse]], Table9[orig]), Table9[char])} -> . | F38: =CODE(Table9[[#This Row],[inv char]]) -> 46 | G38: d | H38: {=_xlfn.XLOOKUP(TRUE, EXACT(Table9[[#This Row],[Complement]], Table9[orig]), Table9[char])} -> d | I38: Y | J38: =Table9[[#This Row],[orig]] & " " -> U
A39: u | B39: u | C39: =CODE(Table9[[#This Row],[char]]) -> 117 | D39: u' | E39: {=_xlfn.XLOOKUP(TRUE, EXACT(Table9[[#This Row],[inverse]], Table9[orig]), Table9[char])} -> - | F39: =CODE(Table9[[#This Row],[inv char]]) -> 45 | G39: D | H39: {=_xlfn.XLOOKUP(TRUE, EXACT(Table9[[#This Row],[Complement]], Table9[orig]), Table9[char])} -> D | I39: Y | J39: =Table9[[#This Row],[orig]] & " " -> u
A40: H | B40: H | C40: =CODE(Table9[[#This Row],[char]]) -> 72 | D40: H' | E40: {=_xlfn.XLOOKUP(TRUE, EXACT(Table9[[#This Row],[inverse]], Table9[orig]), Table9[char])} -> + | F40: =CODE(Table9[[#This Row],[inv char]]) -> 43 | G40: U'D | H40: {=_xlfn.CONCAT(_xlfn.XLOOKUP(TRUE, EXACT(A44, Table9[orig]), Table9[char]), _xlfn.XLOOKUP(TRUE, EXACT(A42, Table9[orig]), Table9[char]))} -> .D | I40: Y | J40: =Table9[[#This Row],[orig]] & " " -> H
...

Sheet table_2
A1: orig | B1: orig char | C1: X | D1: X char | E1: X2 | F1: X2 char | G1: X' | H1: X' char | I1: Y | J1: Y char | K1: Y2 | L1: Y2 char | M1: Y' | N1: Y' char | O1: Z | P1: Z char | Q1: Z2 | R1: Z2 char | S1: Z' | T1: Z' char | U1: T-reflection | V1: T-refl char | W1: H-reflection | X1: H-refl char | Y1: S-reflection | Z1: S-refl char
A2: =Tables!E5 -> R | B2: {=_xlfn.XLOOKUP(TRUE, EXACT(Table2[[#This Row],[orig]], Table9[orig]), Table9[char])} -> R | C2: {=_xlfn.XLOOKUP(TRUE, EXACT(Table2[[#This Row],[orig]], Table4[orig]), Table4[(X)])} -> R | D2: {=_xlfn.XLOOKUP(TRUE, EXACT(Table2[[#This Row],[X]], Table9[orig]), Table9[char])} -> R | E2: {=_xlfn.XLOOKUP(TRUE, EXACT(C2, Table4[orig]), Table4[(X)])} -> R | F2: {=_xlfn.XLOOKUP(TRUE, EXACT(Table2[[#This Row],[X2]], Table9[orig]), Table9[char])} -> R | G2: {=_xlfn.XLOOKUP(TRUE, EXACT(E2, Table4[orig]), Table4[(X)])} -> R | H2: {=_xlfn.XLOOKUP(TRUE, EXACT(Table2[[#This Row],[X'']], Table9[orig]), Table9[char])} -> R | I2: {=_xlfn.XLOOKUP(TRUE, EXACT(Table2[orig], Table1[orig]), Table1[(Y)])} -> F | J2: {=_xlfn.XLOOKUP(TRUE, EXACT(Table2[[#This Row],[Y]], Table9[orig]), Table9[char])} -> F | K2: {=_xlfn.XLOOKUP(TRUE, EXACT(I2, Table1[orig]), Table1[(Y)])} -> L | L2: {=_xlfn.XLOOKUP(TRUE, EXACT(Table2[[#This Row],[Y2]], Table9[orig]), Table9[char])} -> L | M2: {=_xlfn.XLOOKUP(TRUE, EXACT(K2, Table1[orig]), Table1[(Y)])} -> B | N2: {=_xlfn.XLOOKUP(TRUE, EXACT(Table2[[#This Row],[Y'']], Table9[orig]), Table9[char])} -> B | O2: {=_xlfn.XLOOKUP(TRUE, EXACT(Table2[[#This Row],[orig]], Table3[orig]), Table3[(Z)])} -> D | P2: {=_xlfn.XLOOKUP(TRUE, EXACT(Table2[[#This Row],[Z]], Table9[orig]), Table9[char])} -> D | Q2: {=_xlfn.XLOOKUP(TRUE, EXACT(O2, Table3[orig]), Table3[(Z)])} -> L | R2: {=_xlfn.XLOOKUP(TRUE, EXACT(Table2[[#This Row],[Z2]], Table9[orig]), Table9[char])} -> L | S2: {=_xlfn.XLOOKUP(TRUE, EXACT(Q2, Table3[orig]), Table3[(Z)])} -> U | T2: {=_xlfn.XLOOKUP(TRUE, EXACT(Table2[[#This Row],[Z'']], Table9[orig]), Table9[char])} -> U | U2: {=_xlfn.XLOOKUP(TRUE, EXACT(Table2[[#This Row],[orig]], Table5[orig]), Table5[(T-reflection)])} -> L' | V2: {=_xlfn.XLOOKUP(TRUE, EXACT(Table2[[#This Row],[T-reflection]], Table9[orig]), Table9[char])} -> G | W2: {=_xlfn.XLOOKUP(TRUE, EXACT(Table2[[#This Row],[orig]], Table6[orig]), Table6[(H-reflection)])} -> R' | X2: {=_xlfn.XLOOKUP(TRUE, EXACT(Table2[[#This Row],[H-reflection]], Table9[orig]), Table9[char])} -> A | Y2: {=_xlfn.XLOOKUP(TRUE, EXACT(Table2[[#This Row],[orig]], Table7[orig]), Table7[(S-reflection)])} -> R' | Z2: {=_xlfn.XLOOKUP(TRUE, EXACT(Table2[[#This Row],[S-reflection]], Table9[orig]), Table9[char])} -> A
A3: =Tables!E6 -> r | B3: {=_xlfn.XLOOKUP(TRUE, EXACT(Table2[[#This Row],[orig]], Table9[orig]), Table9[char])} -> r | C3: {=_xlfn.XLOOKUP(TRUE, EXACT(Table2[[#This Row],[orig]], Table4[orig]), Table4[(X)])} -> r | D3: {=_xlfn.XLOOKUP(TRUE, EXACT(Table2[[#This Row],[X]], Table9[orig]), Table9[char])} -> r | E3: {=_xlfn.XLOOKUP(TRUE, EXACT(C3, Table4[orig]), Table4[(X)])} -> r | F3: {=_xlfn.XLOOKUP(TRUE, EXACT(Table2[[#This Row],[X2]], Table9[orig]), Table9[char])} -> r | G3: {=_xlfn.XLOOKUP(TRUE, EXACT(E3, Table4[orig]), Table4[(X)])} -> r | H3: {=_xlfn.XLOOKUP(TRUE, EXACT(Table2[[#This Row],[X'']], Table9[orig]), Table9[char])} -> r | I3: {=_xlfn.XLOOKUP(TRUE, EXACT(A3, Table1[orig]), Table1[(Y)])} -> f | J3: {=_xlfn.XLOOKUP(TRUE, EXACT(Table2[[#This Row],[Y]], Table9[orig]), Table9[char])} -> f | K3: {=_xlfn.XLOOKUP(TRUE, EXACT(I3, Table1[orig]), Table1[(Y)])} -> l | L3: {=_xlfn.XLOOKUP(TRUE, EXACT(Table2[[#This Row],[Y2]], Table9[orig]), Table9[char])} -> l | M3: {=_xlfn.XLOOKUP(TRUE, EXACT(K3, Table1[orig]), Table1[(Y)])} -> b | N3: {=_xlfn.XLOOKUP(TRUE, EXACT(Table2[[#This Row],[Y'']], Table9[orig]), Table9[char])} -> b | O3: {=_xlfn.XLOOKUP(TRUE, EXACT(Table2[[#This Row],[orig]], Table3[orig]), Table3[(Z)])} -> d | P3: {=_xlfn.XLOOKUP(TRUE, EXACT(Table2[[#This Row],[Z]], Table9[orig]), Table9[char])} -> d | Q3: {=_xlfn.XLOOKUP(TRUE, EXACT(O3, Table3[orig]), Table3[(Z)])} -> l | R3: {=_xlfn.XLOOKUP(TRUE, EXACT(Table2[[#This Row],[Z2]], Table9[orig]), Table9[char])} -> l | S3: {=_xlfn.XLOOKUP(TRUE, EXACT(Q3, Table3[orig]), Table3[(Z)])} -> u | T3: {=_xlfn.XLOOKUP(TRUE, EXACT(Table2[[#This Row],[Z'']], Table9[orig]), Table9[char])} -> u | U3: {=_xlfn.XLOOKUP(TRUE, EXACT(Table2[[#This Row],[orig]], Table5[orig]), Table5[(T-reflection)])} -> l' | V3: {=_xlfn.XLOOKUP(TRUE, EXACT(Table2[[#This Row],[T-reflection]], Table9[orig]), Table9[char])} -> g | W3: {=_xlfn.XLOOKUP(TRUE, EXACT(Table2[[#This Row],[orig]], Table6[orig]), Table6[(H-reflection)])} -> r' | X3: {=_xlfn.XLOOKUP(TRUE, EXACT(Table2[[#This Row],[H-reflection]], Table9[orig]), Table9[char])} -> a | Y3: {=_xlfn.XLOOKUP(TRUE, EXACT(Table2[[#This Row],[orig]], Table7[orig]), Table7[(S-reflection)])} -> r' | Z3: {=_xlfn.XLOOKUP(TRUE, EXACT(Table2[[#This Row],[S-reflection]], Table9[orig]), Table9[char])} -> a
A4: =Tables!E7 -> T | B4: {=_xlfn.XLOOKUP(TRUE, EXACT(Table2[[#This Row],[orig]], Table9[orig]), Table9[char])} -> T | C4: {=_xlfn.XLOOKUP(TRUE, EXACT(Table2[[#This Row],[orig]], Table4[orig]), Table4[(X)])} -> T | D4: {=_xlfn.XLOOKUP(TRUE, EXACT(Table2[[#This Row],[X]], Table9[orig]), Table9[char])} -> T | E4: {=_xlfn.XLOOKUP(TRUE, EXACT(C4, Table4[orig]), Table4[(X)])} -> T | F4: {=_xlfn.XLOOKUP(TRUE, EXACT(Table2[[#This Row],[X2]], Table9[orig]), Table9[char])} -> T | G4: {=_xlfn.XLOOKUP(TRUE, EXACT(E4, Table4[orig]), Table4[(X)])} -> T | H4: {=_xlfn.XLOOKUP(TRUE, EXACT(Table2[[#This Row],[X'']], Table9[orig]), Table9[char])} -> T | I4: {=_xlfn.XLOOKUP(TRUE, EXACT(A4, Table1[orig]), Table1[(Y)])} -> S | J4: {=_xlfn.XLOOKUP(TRUE, EXACT(Table2[[#This Row],[Y]], Table9[orig]), Table9[char])} -> S | K4: {=_xlfn.XLOOKUP(TRUE, EXACT(I4, Table1[orig]), Table1[(Y)])} -> T' | L4: {=_xlfn.XLOOKUP(TRUE, EXACT(Table2[[#This Row],[Y2]], Table9[orig]), Table9[char])} -> C | M4: {=_xlfn.XLOOKUP(TRUE, EXACT(K4, Table1[orig]), Table1[(Y)])} -> S' | N4: {=_xlfn.XLOOKUP(TRUE, EXACT(Table2[[#This Row],[Y'']], Table9[orig]), Table9[char])} -> V | O4: {=_xlfn.XLOOKUP(TRUE, EXACT(Table2[[#This Row],[orig]], Table3[orig]), Table3[(Z)])} -> H' | P4: {=_xlfn.XLOOKUP(TRUE, EXACT(Table2[[#This Row],[Z]], Table9[orig]), Table9[char])} -> + | Q4: {=_xlfn.XLOOKUP(TRUE, EXACT(O4, Table3[orig]), Table3[(Z)])} -> T' | R4: {=_xlfn.XLOOKUP(TRUE, EXACT(Table2[[#This Row],[Z2]], Table9[orig]), Table9[char])} -> C | S4: {=_xlfn.XLOOKUP(TRUE, EXACT(Q4, Table3[orig]), Table3[(Z)])} -> H | T4: {=_xlfn.XLOOKUP(TRUE, EXACT(Table2[[#This Row],[Z'']], Table9[orig]), Table9[char])} -> H | U4: {=_xlfn.XLOOKUP(TRUE, EXACT(Table2[[#This Row],[orig]], Table5[orig]), Table5[(T-reflection)])} -> T | V4: {=_xlfn.XLOOKUP(TRUE, EXACT(Table2[[#This Row],[T-reflection]], Table9[orig]), Table9[char])} -> T | W4: {=_xlfn.XLOOKUP(TRUE, EXACT(Table2[[#This Row],[orig]], Table6[orig]), Table6[(H-reflection)])} -> T' | X4: {=_xlfn.XLOOKUP(TRUE, EXACT(Table2[[#This Row],[H-reflection]], Table9[orig]), Table9[char])} -> C | Y4: {=_xlfn.XLOOKUP(TRUE, EXACT(Table2[[#This Row],[orig]], Table7[orig]), Table7[(S-reflection)])} -> T' | Z4: {=_xlfn.XLOOKUP(TRUE, EXACT(Table2[[#This Row],[S-reflection]], Table9[orig]), Table9[char])} -> C
A5: =Tables!E8 -> l | B5: {=_xlfn.XLOOKUP(TRUE, EXACT(Table2[[#This Row],[orig]], Table9[orig]), Table9[char])} -> l | C5: {=_xlfn.XLOOKUP(TRUE, EXACT(Table2[[#This Row],[orig]], Table4[orig]), Table4[(X)])} -> l | D5: {=_xlfn.XLOOKUP(TRUE, EXACT(Table2[[#This Row],[X]], Table9[orig]), Table9[char])} -> l | E5: {=_xlfn.XLOOKUP(TRUE, EXACT(C5, Table4[orig]), Table4[(X)])} -> l | F5: {=_xlfn.XLOOKUP(TRUE, EXACT(Table2[[#This Row],[X2]], Table9[orig]), Table9[char])} -> l | G5: {=_xlfn.XLOOKUP(TRUE, EXACT(E5, Table4[orig]), Table4[(X)])} -> l | H5: {=_xlfn.XLOOKUP(TRUE, EXACT(Table2[[#This Row],[X'']], Table9[orig]), Table9[char])} -> l | I5: {=_xlfn.XLOOKUP(TRUE, EXACT(A5, Table1[orig]), Table1[(Y)])} -> b | J5: {=_xlfn.XLOOKUP(TRUE, EXACT(Table2[[#This Row],[Y]], Table9[orig]), Table9[char])} -> b | K5: {=_xlfn.XLOOKUP(TRUE, EXACT(I5, Table1[orig]), Table1[(Y)])} -> r | L5: {=_xlfn.XLOOKUP(TRUE, EXACT(Table2[[#This Row],[Y2]], Table9[orig]), Table9[char])} -> r | M5: {=_xlfn.XLOOKUP(TRUE, EXACT(K5, Table1[orig]), Table1[(Y)])} -> f | N5: {=_xlfn.XLOOKUP(TRUE, EXACT(Table2[[#This Row],[Y'']], Table9[orig]), Table9[char])} -> f | O5: {=_xlfn.XLOOKUP(TRUE, EXACT(Table2[[#This Row],[orig]], Table3[orig]), Table3[(Z)])} -> u | P5: {=_xlfn.XLOOKUP(TRUE, EXACT(Table2[[#This Row],[Z]], Table9[orig]), Table9[char])} -> u | Q5: {=_xlfn.XLOOKUP(TRUE, EXACT(O5, Table3[orig]), Table3[(Z)])} -> r | R5: {=_xlfn.XLOOKUP(TRUE, EXACT(Table2[[#This Row],[Z2]], Table9[orig]), Table9[char])} -> r | S5: {=_xlfn.XLOOKUP(TRUE, EXACT(Q5, Table3[orig]), Table3[(Z)])} -> d | T5: {=_xlfn.XLOOKUP(TRUE, EXACT(Table2[[#This Row],[Z'']], Table9[orig]), Table9[char])} -> d | U5: {=_xlfn.XLOOKUP(TRUE, EXACT(Table2[[#This Row],[orig]], Table5[orig]), Table5[(T-reflection)])} -> r' | V5: {=_xlfn.XLOOKUP(TRUE, EXACT(Table2[[#This Row],[T-reflection]], Table9[orig]), Table9[char])} -> a | W5: {=_xlfn.XLOOKUP(TRUE, EXACT(Table2[[#This Row],[orig]], Table6[orig]), Table6[(H-reflection)])} -> l' | X5: {=_xlfn.XLOOKUP(TRUE, EXACT(Table2[[#This Row],[H-reflection]], Table9[orig]), Table9[char])} -> g | Y5: {=_xlfn.XLOOKUP(TRUE, EXACT(Table2[[#This Row],[orig]], Table7[orig]), Table7[(S-reflection)])} -> l' | Z5: {=_xlfn.XLOOKUP(TRUE, EXACT(Table2[[#This Row],[S-reflection]], Table9[orig]), Table9[char])} -> g
A6: =Tables!E9 -> L | B6: {=_xlfn.XLOOKUP(TRUE, EXACT(Table2[[#This Row],[orig]], Table9[orig]), Table9[char])} -> L | C6: {=_xlfn.XLOOKUP(TRUE, EXACT(Table2[[#This Row],[orig]], Table4[orig]), Table4[(X)])} -> L | D6: {=_xlfn.XLOOKUP(TRUE, EXACT(Table2[[#This Row],[X]], Table9[orig]), Table9[char])} -> L | E6: {=_xlfn.XLOOKUP(TRUE, EXACT(C6, Table4[orig]), Table4[(X)])} -> L | F6: {=_xlfn.XLOOKUP(TRUE, EXACT(Table2[[#This Row],[X2]], Table9[orig]), Table9[char])} -> L | G6: {=_xlfn.XLOOKUP(TRUE, EXACT(E6, Table4[orig]), Table4[(X)])} -> L | H6: {=_xlfn.XLOOKUP(TRUE, EXACT(Table2[[#This Row],[X'']], Table9[orig]), Table9[char])} -> L | I6: {=_xlfn.XLOOKUP(TRUE, EXACT(A6, Table1[orig]), Table1[(Y)])} -> B | J6: {=_xlfn.XLOOKUP(TRUE, EXACT(Table2[[#This Row],[Y]], Table9[orig]), Table9[char])} -> B | K6: {=_xlfn.XLOOKUP(TRUE, EXACT(I6, Table1[orig]), Table1[(Y)])} -> R | L6: {=_xlfn.XLOOKUP(TRUE, EXACT(Table2[[#This Row],[Y2]], Table9[orig]), Table9[char])} -> R | M6: {=_xlfn.XLOOKUP(TRUE, EXACT(K6, Table1[orig]), Table1[(Y)])} -> F | N6: {=_xlfn.XLOOKUP(TRUE, EXACT(Table2[[#This Row],[Y'']], Table9[orig]), Table9[char])} -> F | O6: {=_xlfn.XLOOKUP(TRUE, EXACT(Table2[[#This Row],[orig]], Table3[orig]), Table3[(Z)])} -> U | P6: {=_xlfn.XLOOKUP(TRUE, EXACT(Table2[[#This Row],[Z]], Table9[orig]), Table9[char])} -> U | Q6: {=_xlfn.XLOOKUP(TRUE, EXACT(O6, Table3[orig]), Table3[(Z)])} -> R | R6: {=_xlfn.XLOOKUP(TRUE, EXACT(Table2[[#This Row],[Z2]], Table9[orig]), Table9[char])} -> R | S6: {=_xlfn.XLOOKUP(TRUE, EXACT(Q6, Table3[orig]), Table3[(Z)])} -> D | T6: {=_xlfn.XLOOKUP(TRUE, EXACT(Table2[[#This Row],[Z'']], Table9[orig]), Table9[char])} -> D | U6: {=_xlfn.XLOOKUP(TRUE, EXACT(Table2[[#This Row],[orig]], Table5[orig]), Table5[(T-reflection)])} -> R' | V6: {=_xlfn.XLOOKUP(TRUE, EXACT(Table2[[#This Row],[T-reflection]], Table9[orig]), Table9[char])} -> A | W6: {=_xlfn.XLOOKUP(TRUE, EXACT(Table2[[#This Row],[orig]], Table6[orig]), Table6[(H-reflection)])} -> L' | X6: {=_xlfn.XLOOKUP(TRUE, EXACT(Table2[[#This Row],[H-reflection]], Table9[orig]), Table9[char])} -> G | Y6: {=_xlfn.XLOOKUP(TRUE, EXACT(Table2[[#This Row],[orig]], Table7[orig]), Table7[(S-reflection)])} -> L' | Z6: {=_xlfn.XLOOKUP(TRUE, EXACT(Table2[[#This Row],[S-reflection]], Table9[orig]), Table9[char])} -> G
A7: =Tables!E10 -> X | B7: {=_xlfn.XLOOKUP(TRUE, EXACT(Table2[[#This Row],[orig]], Table9[orig]), Table9[char])} -> X | C7: {=_xlfn.XLOOKUP(TRUE, EXACT(Table2[[#This Row],[orig]], Table4[orig]), Table4[(X)])} -> X | D7: {=_xlfn.XLOOKUP(TRUE, EXACT(Table2[[#This Row],[X]], Table9[orig]), Table9[char])} -> X | E7: {=_xlfn.XLOOKUP(TRUE, EXACT(C7, Table4[orig]), Table4[(X)])} -> X | F7: {=_xlfn.XLOOKUP(TRUE, EXACT(Table2[[#This Row],[X2]], Table9[orig]), Table9[char])} -> X | G7: {=_xlfn.XLOOKUP(TRUE, EXACT(E7, Table4[orig]), Table4[(X)])} -> X | H7: {=_xlfn.XLOOKUP(TRUE, EXACT(Table2[[#This Row],[X'']], Table9[orig]), Table9[char])} -> X | I7: {=_xlfn.XLOOKUP(TRUE, EXACT(A7, Table1[orig]), Table1[(Y)])} -> Z | J7: {=_xlfn.XLOOKUP(TRUE, EXACT(Table2[[#This Row],[Y]], Table9[orig]), Table9[char])} -> Z | K7: {=_xlfn.XLOOKUP(TRUE, EXACT(I7, Table1[orig]), Table1[(Y)])} -> X' | L7: {=_xlfn.XLOOKUP(TRUE, EXACT(Table2[[#This Row],[Y2]], Table9[orig]), Table9[char])} -> ! | M7: {=_xlfn.XLOOKUP(TRUE, EXACT(K7, Table1[orig]), Table1[(Y)])} -> Z' | N7: {=_xlfn.XLOOKUP(TRUE, EXACT(Table2[[#This Row],[Y'']], Table9[orig]), Table9[char])} -> # | O7: {=_xlfn.XLOOKUP(TRUE, EXACT(Table2[[#This Row],[orig]], Table3[orig]), Table3[(Z)])} -> Y' | P7: {=_xlfn.XLOOKUP(TRUE, EXACT(Table2[[#This Row],[Z]], Table9[orig]), Table9[char])} -> p | Q7: {=_xlfn.XLOOKUP(TRUE, EXACT(O7, Table3[orig]), Table3[(Z)])} -> X' | R7: {=_xlfn.XLOOKUP(TRUE, EXACT(Table2[[#This Row],[Z2]], Table9[orig]), Table9[char])} -> ! | S7: {=_xlfn.XLOOKUP(TRUE, EXACT(Q7, Table3[orig]), Table3[(Z)])} -> Y | T7: {=_xlfn.XLOOKUP(TRUE, EXACT(Table2[[#This Row],[Z'']], Table9[orig]), Table9[char])} -> Y | U7: {=_xlfn.XLOOKUP(TRUE, EXACT(Table2[[#This Row],[orig]], Table5[orig]), Table5[(T-reflection)])} -> X | V7: {=_xlfn.XLOOKUP(TRUE, EXACT(Table2[[#This Row],[T-reflection]], Table9[orig]), Table9[char])} -> X | W7: {=_xlfn.XLOOKUP(TRUE, EXACT(Table2[[#This Row],[orig]], Table6[orig]), Table6[(H-reflection)])} -> X' | X7: {=_xlfn.XLOOKUP(TRUE, EXACT(Table2[[#This Row],[H-reflection]], Table9[orig]), Table9[char])} -> ! | Y7: {=_xlfn.XLOOKUP(TRUE, EXACT(Table2[[#This Row],[orig]], Table7[orig]), Table7[(S-reflection)])} -> X' | Z7: {=_xlfn.XLOOKUP(TRUE, EXACT(Table2[[#This Row],[S-reflection]], Table9[orig]), Table9[char])} -> !
A8: =Tables!E11 -> R' | B8: {=_xlfn.XLOOKUP(TRUE, EXACT(Table2[[#This Row],[orig]], Table9[orig]), Table9[char])} -> A | C8: {=_xlfn.XLOOKUP(TRUE, EXACT(Table2[[#This Row],[orig]], Table4[orig]), Table4[(X)])} -> R' | D8: {=_xlfn.XLOOKUP(TRUE, EXACT(Table2[[#This Row],[X]], Table9[orig]), Table9[char])} -> A | E8: {=_xlfn.XLOOKUP(TRUE, EXACT(C8, Table4[orig]), Table4[(X)])} -> R' | F8: {=_xlfn.XLOOKUP(TRUE, EXACT(Table2[[#This Row],[X2]], Table9[orig]), Table9[char])} -> A | G8: {=_xlfn.XLOOKUP(TRUE, EXACT(E8, Table4[orig]), Table4[(X)])} -> R' | H8: {=_xlfn.XLOOKUP(TRUE, EXACT(Table2[[#This Row],[X'']], Table9[orig]), Table9[char])} -> A | I8: {=_xlfn.XLOOKUP(TRUE, EXACT(A8, Table1[orig]), Table1[(Y)])} -> F' | J8: {=_xlfn.XLOOKUP(TRUE, EXACT(Table2[[#This Row],[Y]], Table9[orig]), Table9[char])} -> Q | K8: {=_xlfn.XLOOKUP(TRUE, EXACT(I8, Table1[orig]), Table1[(Y)])} -> L' | L8: {=_xlfn.XLOOKUP(TRUE, EXACT(Table2[[#This Row],[Y2]], Table9[orig]), Table9[char])} -> G | M8: {=_xlfn.XLOOKUP(TRUE, EXACT(K8, Table1[orig]), Table1[(Y)])} -> B' | N8: {=_xlfn.XLOOKUP(TRUE, EXACT(Table2[[#This Row],[Y'']], Table9[orig]), Table9[char])} -> @ | O8: {=_xlfn.XLOOKUP(TRUE, EXACT(Table2[[#This Row],[orig]], Table3[orig]), Table3[(Z)])} -> D' | P8: {=_xlfn.XLOOKUP(TRUE, EXACT(Table2[[#This Row],[Z]], Table9[orig]), Table9[char])} -> % | Q8: {=_xlfn.XLOOKUP(TRUE, EXACT(O8, Table3[orig]), Table3[(Z)])} -> L' | R8: {=_xlfn.XLOOKUP(TRUE, EXACT(Table2[[#This Row],[Z2]], Table9[orig]), Table9[char])} -> G | S8: {=_xlfn.XLOOKUP(TRUE, EXACT(Q8, Table3[orig]), Table3[(Z)])} -> U' | T8: {=_xlfn.XLOOKUP(TRUE, EXACT(Table2[[#This Row],[Z'']], Table9[orig]), Table9[char])} -> . | U8: {=_xlfn.XLOOKUP(TRUE, EXACT(Table2[[#This Row],[orig]], Table5[orig]), Table5[(T-reflection)])} -> L | V8: {=_xlfn.XLOOKUP(TRUE, EXACT(Table2[[#This Row],[T-reflection]], Table9[orig]), Table9[char])} -> L | W8: {=_xlfn.XLOOKUP(TRUE, EXACT(Table2[[#This Row],[orig]], Table6[orig]), Table6[(H-reflection)])} -> R | X8: {=_xlfn.XLOOKUP(TRUE, EXACT(Table2[[#This Row],[H-reflection]], Table9[orig]), Table9[char])} -> R | Y8: {=_xlfn.XLOOKUP(TRUE, EXACT(Table2[[#This Row],[orig]], Table7[orig]), Table7[(S-reflection)])} -> R | Z8: {=_xlfn.XLOOKUP(TRUE, EXACT(Table2[[#This Row],[S-reflection]], Table9[orig]), Table9[char])} -> R
A9: =Tables!E12 -> r' | B9: {=_xlfn.XLOOKUP(TRUE, EXACT(Table2[[#This Row],[orig]], Table9[orig]), Table9[char])} -> a | C9: {=_xlfn.XLOOKUP(TRUE, EXACT(Table2[[#This Row],[orig]], Table4[orig]), Table4[(X)])} -> r' | D9: {=_xlfn.XLOOKUP(TRUE, EXACT(Table2[[#This Row],[X]], Table9[orig]), Table9[char])} -> a | E9: {=_xlfn.XLOOKUP(TRUE, EXACT(C9, Table4[orig]), Table4[(X)])} -> r' | F9: {=_xlfn.XLOOKUP(TRUE, EXACT(Table2[[#This Row],[X2]], Table9[orig]), Table9[char])} -> a | G9: {=_xlfn.XLOOKUP(TRUE, EXACT(E9, Table4[orig]), Table4[(X)])} -> r' | H9: {=_xlfn.XLOOKUP(TRUE, EXACT(Table2[[#This Row],[X'']], Table9[orig]), Table9[char])} -> a | I9: {=_xlfn.XLOOKUP(TRUE, EXACT(A9, Table1[orig]), Table1[(Y)])} -> f' | J9: {=_xlfn.XLOOKUP(TRUE, EXACT(Table2[[#This Row],[Y]], Table9[orig]), Table9[char])} -> q | K9: {=_xlfn.XLOOKUP(TRUE, EXACT(I9, Table1[orig]), Table1[(Y)])} -> l' | L9: {=_xlfn.XLOOKUP(TRUE, EXACT(Table2[[#This Row],[Y2]], Table9[orig]), Table9[char])} -> g | M9: {=_xlfn.XLOOKUP(TRUE, EXACT(K9, Table1[orig]), Table1[(Y)])} -> b' | N9: {=_xlfn.XLOOKUP(TRUE, EXACT(Table2[[#This Row],[Y'']], Table9[orig]), Table9[char])} -> & | O9: {=_xlfn.XLOOKUP(TRUE, EXACT(Table2[[#This Row],[orig]], Table3[orig]), Table3[(Z)])} -> d' | P9: {=_xlfn.XLOOKUP(TRUE, EXACT(Table2[[#This Row],[Z]], Table9[orig]), Table9[char])} -> k | Q9: {=_xlfn.XLOOKUP(TRUE, EXACT(O9, Table3[orig]), Table3[(Z)])} -> l' | R9: {=_xlfn.XLOOKUP(TRUE, EXACT(Table2[[#This Row],[Z2]], Table9[orig]), Table9[char])} -> g | S9: {=_xlfn.XLOOKUP(TRUE, EXACT(Q9, Table3[orig]), Table3[(Z)])} -> u' | T9: {=_xlfn.XLOOKUP(TRUE, EXACT(Table2[[#This Row],[Z'']], Table9[orig]), Table9[char])} -> - | U9: {=_xlfn.XLOOKUP(TRUE, EXACT(Table2[[#This Row],[orig]], Table5[orig]), Table5[(T-reflection)])} -> l | V9: {=_xlfn.XLOOKUP(TRUE, EXACT(Table2[[#This Row],[T-reflection]], Table9[orig]), Table9[char])} -> l | W9: {=_xlfn.XLOOKUP(TRUE, EXACT(Table2[[#This Row],[orig]], Table6[orig]), Table6[(H-reflection)])} -> r | X9: {=_xlfn.XLOOKUP(TRUE, EXACT(Table2[[#This Row],[H-reflection]], Table9[orig]), Table9[char])} -> r | Y9: {=_xlfn.XLOOKUP(TRUE, EXACT(Table2[[#This Row],[orig]], Table7[orig]), Table7[(S-reflection)])} -> r | Z9: {=_xlfn.XLOOKUP(TRUE, EXACT(Table2[[#This Row],[S-reflection]], Table9[orig]), Table9[char])} -> r
A10: =Tables!E13 -> T' | B10: {=_xlfn.XLOOKUP(TRUE, EXACT(Table2[[#This Row],[orig]], Table9[orig]), Table9[char])} -> C | C10: {=_xlfn.XLOOKUP(TRUE, EXACT(Table2[[#This Row],[orig]], Table4[orig]), Table4[(X)])} -> T' | D10: {=_xlfn.XLOOKUP(TRUE, EXACT(Table2[[#This Row],[X]], Table9[orig]), Table9[char])} -> C | E10: {=_xlfn.XLOOKUP(TRUE, EXACT(C10, Table4[orig]), Table4[(X)])} -> T' | F10: {=_xlfn.XLOOKUP(TRUE, EXACT(Table2[[#This Row],[X2]], Table9[orig]), Table9[char])} -> C | G10: {=_xlfn.XLOOKUP(TRUE, EXACT(E10, Table4[orig]), Table4[(X)])} -> T' | H10: {=_xlfn.XLOOKUP(TRUE, EXACT(Table2[[#This Row],[X'']], Table9[orig]), Table9[char])} -> C | I10: {=_xlfn.XLOOKUP(TRUE, EXACT(A10, Table1[orig]), Table1[(Y)])} -> S' | J10: {=_xlfn.XLOOKUP(TRUE, EXACT(Table2[[#This Row],[Y]], Table9[orig]), Table9[char])} -> V | K10: {=_xlfn.XLOOKUP(TRUE, EXACT(I10, Table1[orig]), Table1[(Y)])} -> T | L10: {=_xlfn.XLOOKUP(TRUE, EXACT(Table2[[#This Row],[Y2]], Table9[orig]), Table9[char])} -> T | M10: {=_xlfn.XLOOKUP(TRUE, EXACT(K10, Table1[orig]), Table1[(Y)])} -> S | N10: {=_xlfn.XLOOKUP(TRUE, EXACT(Table2[[#This Row],[Y'']], Table9[orig]), Table9[char])} -> S | O10: {=_xlfn.XLOOKUP(TRUE, EXACT(Table2[[#This Row],[orig]], Table3[orig]), Table3[(Z)])} -> H | P10: {=_xlfn.XLOOKUP(TRUE, EXACT(Table2[[#This Row],[Z]], Table9[orig]), Table9[char])} -> H | Q10: {=_xlfn.XLOOKUP(TRUE, EXACT(O10, Table3[orig]), Table3[(Z)])} -> T | R10: {=_xlfn.XLOOKUP(TRUE, EXACT(Table2[[#This Row],[Z2]], Table9[orig]), Table9[char])} -> T | S10: {=_xlfn.XLOOKUP(TRUE, EXACT(Q10, Table3[orig]), Table3[(Z)])} -> H' | T10: {=_xlfn.XLOOKUP(TRUE, EXACT(Table2[[#This Row],[Z'']], Table9[orig]), Table9[char])} -> + | U10: {=_xlfn.XLOOKUP(TRUE, EXACT(Table2[[#This Row],[orig]], Table5[orig]), Table5[(T-reflection)])} -> T' | V10: {=_xlfn.XLOOKUP(TRUE, EXACT(Table2[[#This Row],[T-reflection]], Table9[orig]), Table9[char])} -> C | W10: {=_xlfn.XLOOKUP(TRUE, EXACT(Table2[[#This Row],[orig]], Table6[orig]), Table6[(H-reflection)])} -> T | X10: {=_xlfn.XLOOKUP(TRUE, EXACT(Table2[[#This Row],[H-reflection]], Table9[orig]), Table9[char])} -> T | Y10: {=_xlfn.XLOOKUP(TRUE, EXACT(Table2[[#This Row],[orig]], Table7[orig]), Table7[(S-reflection)])} -> T | Z10: {=_xlfn.XLOOKUP(TRUE, EXACT(Table2[[#This Row],[S-reflection]], Table9[orig]), Table9[char])} -> T
A11: =Tables!E14 -> l' | B11: {=_xlfn.XLOOKUP(TRUE, EXACT(Table2[[#This Row],[orig]], Table9[orig]), Table9[char])} -> g | C11: {=_xlfn.XLOOKUP(TRUE, EXACT(Table2[[#This Row],[orig]], Table4[orig]), Table4[(X)])} -> l' | D11: {=_xlfn.XLOOKUP(TRUE, EXACT(Table2[[#This Row],[X]], Table9[orig]), Table9[char])} -> g | E11: {=_xlfn.XLOOKUP(TRUE, EXACT(C11, Table4[orig]), Table4[(X)])} -> l' | F11: {=_xlfn.XLOOKUP(TRUE, EXACT(Table2[[#This Row],[X2]], Table9[orig]), Table9[char])} -> g | G11: {=_xlfn.XLOOKUP(TRUE, EXACT(E11, Table4[orig]), Table4[(X)])} -> l' | H11: {=_xlfn.XLOOKUP(TRUE, EXACT(Table2[[#This Row],[X'']], Table9[orig]), Table9[char])} -> g | I11: {=_xlfn.XLOOKUP(TRUE, EXACT(A11, Table1[orig]), Table1[(Y)])} -> b' | J11: {=_xlfn.XLOOKUP(TRUE, EXACT(Table2[[#This Row],[Y]], Table9[orig]), Table9[char])} -> & | K11: {=_xlfn.XLOOKUP(TRUE, EXACT(I11, Table1[orig]), Table1[(Y)])} -> r' | L11: {=_xlfn.XLOOKUP(TRUE, EXACT(Table2[[#This Row],[Y2]], Table9[orig]), Table9[char])} -> a | M11: {=_xlfn.XLOOKUP(TRUE, EXACT(K11, Table1[orig]), Table1[(Y)])} -> f' | N11: {=_xlfn.XLOOKUP(TRUE, EXACT(Table2[[#This Row],[Y'']], Table9[orig]), Table9[char])} -> q | O11: {=_xlfn.XLOOKUP(TRUE, EXACT(Table2[[#This Row],[orig]], Table3[orig]), Table3[(Z)])} -> u' | P11: {=_xlfn.XLOOKUP(TRUE, EXACT(Table2[[#This Row],[Z]], Table9[orig]), Table9[char])} -> - | Q11: {=_xlfn.XLOOKUP(TRUE, EXACT(O11, Table3[orig]), Table3[(Z)])} -> r' | R11: {=_xlfn.XLOOKUP(TRUE, EXACT(Table2[[#This Row],[Z2]], Table9[orig]), Table9[char])} -> a | S11: {=_xlfn.XLOOKUP(TRUE, EXACT(Q11, Table3[orig]), Table3[(Z)])} -> d' | T11: {=_xlfn.XLOOKUP(TRUE, EXACT(Table2[[#This Row],[Z'']], Table9[orig]), Table9[char])} -> k | U11: {=_xlfn.XLOOKUP(TRUE, EXACT(Table2[[#This Row],[orig]], Table5[orig]), Table5[(T-reflection)])} -> r | V11: {=_xlfn.XLOOKUP(TRUE, EXACT(Table2[[#This Row],[T-reflection]], Table9[orig]), Table9[char])} -> r | W11: {=_xlfn.XLOOKUP(TRUE, EXACT(Table2[[#This Row],[orig]], Table6[orig]), Table6[(H-reflection)])} -> l | X11: {=_xlfn.XLOOKUP(TRUE, EXACT(Table2[[#This Row],[H-reflection]], Table9[orig]), Table9[char])} -> l | Y11: {=_xlfn.XLOOKUP(TRUE, EXACT(Table2[[#This Row],[orig]], Table7[orig]), Table7[(S-reflection)])} -> l | Z11: {=_xlfn.XLOOKUP(TRUE, EXACT(Table2[[#This Row],[S-reflection]], Table9[orig]), Table9[char])} -> l
A12: =Tables!E15 -> L' | B12: {=_xlfn.XLOOKUP(TRUE, EXACT(Table2[[#This Row],[orig]], Table9[orig]), Table9[char])} -> G | C12: {=_xlfn.XLOOKUP(TRUE, EXACT(Table2[[#This Row],[orig]], Table4[orig]), Table4[(X)])} -> L' | D12: {=_xlfn.XLOOKUP(TRUE, EXACT(Table2[[#This Row],[X]], Table9[orig]), Table9[char])} -> G | E12: {=_xlfn.XLOOKUP(TRUE, EXACT(C12, Table4[orig]), Table4[(X)])} -> L' | F12: {=_xlfn.XLOOKUP(TRUE, EXACT(Table2[[#This Row],[X2]], Table9[orig]), Table9[char])} -> G | G12: {=_xlfn.XLOOKUP(TRUE, EXACT(E12, Table4[orig]), Table4[(X)])} -> L' | H12: {=_xlfn.XLOOKUP(TRUE, EXACT(Table2[[#This Row],[X'']], Table9[orig]), Table9[char])} -> G | I12: {=_xlfn.XLOOKUP(TRUE, EXACT(A12, Table1[orig]), Table1[(Y)])} -> B' | J12: {=_xlfn.XLOOKUP(TRUE, EXACT(Table2[[#This Row],[Y]], Table9[orig]), Table9[char])} -> @ | K12: {=_xlfn.XLOOKUP(TRUE, EXACT(I12, Table1[orig]), Table1[(Y)])} -> R' | L12: {=_xlfn.XLOOKUP(TRUE, EXACT(Table2[[#This Row],[Y2]], Table9[orig]), Table9[char])} -> A | M12: {=_xlfn.XLOOKUP(TRUE, EXACT(K12, Table1[orig]), Table1[(Y)])} -> F' | N12: {=_xlfn.XLOOKUP(TRUE, EXACT(Table2[[#This Row],[Y'']], Table9[orig]), Table9[char])} -> Q | O12: {=_xlfn.XLOOKUP(TRUE, EXACT(Table2[[#This Row],[orig]], Table3[orig]), Table3[(Z)])} -> U' | P12: {=_xlfn.XLOOKUP(TRUE, EXACT(Table2[[#This Row],[Z]], Table9[orig]), Table9[char])} -> . | Q12: {=_xlfn.XLOOKUP(TRUE, EXACT(O12, Table3[orig]), Table3[(Z)])} -> R' | R12: {=_xlfn.XLOOKUP(TRUE, EXACT(Table2[[#This Row],[Z2]], Table9[orig]), Table9[char])} -> A | S12: {=_xlfn.XLOOKUP(TRUE, EXACT(Q12, Table3[orig]), Table3[(Z)])} -> D' | T12: {=_xlfn.XLOOKUP(TRUE, EXACT(Table2[[#This Row],[Z'']], Table9[orig]), Table9[char])} -> % | U12: {=_xlfn.XLOOKUP(TRUE, EXACT(Table2[[#This Row],[orig]], Table5[orig]), Table5[(T-reflection)])} -> R | V12: {=_xlfn.XLOOKUP(TRUE, EXACT(Table2[[#This Row],[T-reflection]], Table9[orig]), Table9[char])} -> R | W12: {=_xlfn.XLOOKUP(TRUE, EXACT(Table2[[#This Row],[orig]], Table6[orig]), Table6[(H-reflection)])} -> L | X12: {=_xlfn.XLOOKUP(TRUE, EXACT(Table2[[#This Row],[H-reflection]], Table9[orig]), Table9[char])} -> L | Y12: {=_xlfn.XLOOKUP(TRUE, EXACT(Table2[[#This Row],[orig]], Table7[orig]), Table7[(S-reflection)])} -> L | Z12: {=_xlfn.XLOOKUP(TRUE, EXACT(Table2[[#This Row],[S-reflection]], Table9[orig]), Table9[char])} -> L
A13: =Tables!E16 -> X' | B13: {=_xlfn.XLOOKUP(TRUE, EXACT(Table2[[#This Row],[orig]], Table9[orig]), Table9[char])} -> ! | C13: {=_xlfn.XLOOKUP(TRUE, EXACT(Table2[[#This Row],[orig]], Table4[orig]), Table4[(X)])} -> X' | D13: {=_xlfn.XLOOKUP(TRUE, EXACT(Table2[[#This Row],[X]], Table9[orig]), Table9[char])} -> ! | E13: {=_xlfn.XLOOKUP(TRUE, EXACT(C13, Table4[orig]), Table4[(X)])} -> X' | F13: {=_xlfn.XLOOKUP(TRUE, EXACT(Table2[[#This Row],[X2]], Table9[orig]), Table9[char])} -> ! | G13: {=_xlfn.XLOOKUP(TRUE, EXACT(E13, Table4[orig]), Table4[(X)])} -> X' | H13: {=_xlfn.XLOOKUP(TRUE, EXACT(Table2[[#This Row],[X'']], Table9[orig]), Table9[char])} -> ! | I13: {=_xlfn.XLOOKUP(TRUE, EXACT(A13, Table1[orig]), Table1[(Y)])} -> Z' | J13: {=_xlfn.XLOOKUP(TRUE, EXACT(Table2[[#This Row],[Y]], Table9[orig]), Table9[char])} -> # | K13: {=_xlfn.XLOOKUP(TRUE, EXACT(I13, Table1[orig]), Table1[(Y)])} -> X | L13: {=_xlfn.XLOOKUP(TRUE, EXACT(Table2[[#This Row],[Y2]], Table9[orig]), Table9[char])} -> X | M13: {=_xlfn.XLOOKUP(TRUE, EXACT(K13, Table1[orig]), Table1[(Y)])} -> Z | N13: {=_xlfn.XLOOKUP(TRUE, EXACT(Table2[[#This Row],[Y'']], Table9[orig]), Table9[char])} -> Z | O13: {=_xlfn.XLOOKUP(TRUE, EXACT(Table2[[#This Row],[orig]], Table3[orig]), Table3[(Z)])} -> Y | P13: {=_xlfn.XLOOKUP(TRUE, EXACT(Table2[[#This Row],[Z]], Table9[orig]), Table9[char])} -> Y | Q13: {=_xlfn.XLOOKUP(TRUE, EXACT(O13, Table3[orig]), Table3[(Z)])} -> X | R13: {=_xlfn.XLOOKUP(TRUE, EXACT(Table2[[#This Row],[Z2]], Table9[orig]), Table9[char])} -> X | S13: {=_xlfn.XLOOKUP(TRUE, EXACT(Q13, Table3[orig]), Table3[(Z)])} -> Y' | T13: {=_xlfn.XLOOKUP(TRUE, EXACT(Table2[[#This Row],[Z'']], Table9[orig]), Table9[char])} -> p | U13: {=_xlfn.XLOOKUP(TRUE, EXACT(Table2[[#This Row],[orig]], Table5[orig]), Table5[(T-reflection)])} -> X' | V13: {=_xlfn.XLOOKUP(TRUE, EXACT(Table2[[#This Row],[T-reflection]], Table9[orig]), Table9[char])} -> ! | W13: {=_xlfn.XLOOKUP(TRUE, EXACT(Table2[[#This Row],[orig]], Table6[orig]), Table6[(H-reflection)])} -> X | X13: {=_xlfn.XLOOKUP(TRUE, EXACT(Table2[[#This Row],[H-reflection]], Table9[orig]), Table9[char])} -> X | Y13: {=_xlfn.XLOOKUP(TRUE, EXACT(Table2[[#This Row],[orig]], Table7[orig]), Table7[(S-reflection)])} -> X | Z13: {=_xlfn.XLOOKUP(TRUE, EXACT(Table2[[#This Row],[S-reflection]], Table9[orig]), Table9[char])} -> X
A14: =Tables!E17 -> R2 | B14: {=_xlfn.XLOOKUP(TRUE, EXACT(Table2[[#This Row],[orig]], Table9[orig]), Table9[char])} -> J | C14: {=_xlfn.XLOOKUP(TRUE, EXACT(Table2[[#This Row],[orig]], Table4[orig]), Table4[(X)])} -> R2 | D14: {=_xlfn.XLOOKUP(TRUE, EXACT(Table2[[#This Row],[X]], Table9[orig]), Table9[char])} -> J | E14: {=_xlfn.XLOOKUP(TRUE, EXACT(C14, Table4[orig]), Table4[(X)])} -> R2 | F14: {=_xlfn.XLOOKUP(TRUE, EXACT(Table2[[#This Row],[X2]], Table9[orig]), Table9[char])} -> J | G14: {=_xlfn.XLOOKUP(TRUE, EXACT(E14, Table4[orig]), Table4[(X)])} -> R2 | H14: {=_xlfn.XLOOKUP(TRUE, EXACT(Table2[[#This Row],[X'']], Table9[orig]), Table9[char])} -> J | I14: {=_xlfn.XLOOKUP(TRUE, EXACT(A14, Table1[orig]), Table1[(Y)])} -> F2 | J14: {=_xlfn.XLOOKUP(TRUE, EXACT(Table2[[#This Row],[Y]], Table9[orig]), Table9[char])} -> $ | K14: {=_xlfn.XLOOKUP(TRUE, EXACT(I14, Table1[orig]), Table1[(Y)])} -> L2 | L14: {=_xlfn.XLOOKUP(TRUE, EXACT(Table2[[#This Row],[Y2]], Table9[orig]), Table9[char])} -> N | M14: {=_xlfn.XLOOKUP(TRUE, EXACT(K14, Table1[orig]), Table1[(Y)])} -> B2 | N14: {=_xlfn.XLOOKUP(TRUE, EXACT(Table2[[#This Row],[Y'']], Table9[orig]), Table9[char])} -> ` | O14: {=_xlfn.XLOOKUP(TRUE, EXACT(Table2[[#This Row],[orig]], Table3[orig]), Table3[(Z)])} -> D2 | P14: {=_xlfn.XLOOKUP(TRUE, EXACT(Table2[[#This Row],[Z]], Table9[orig]), Table9[char])} -> c | Q14: {=_xlfn.XLOOKUP(TRUE, EXACT(O14, Table3[orig]), Table3[(Z)])} -> L2 | R14: {=_xlfn.XLOOKUP(TRUE, EXACT(Table2[[#This Row],[Z2]], Table9[orig]), Table9[char])} -> N | S14: {=_xlfn.XLOOKUP(TRUE, EXACT(Q14, Table3[orig]), Table3[(Z)])} -> U2 | T14: {=_xlfn.XLOOKUP(TRUE, EXACT(Table2[[#This Row],[Z'']], Table9[orig]), Table9[char])} -> \ | U14: {=_xlfn.XLOOKUP(TRUE, EXACT(Table2[[#This Row],[orig]], Table5[orig]), Table5[(T-reflection)])} -> L2 | V14: {=_xlfn.XLOOKUP(TRUE, EXACT(Table2[[#This Row],[T-reflection]], Table9[orig]), Table9[char])} -> N | W14: {=_xlfn.XLOOKUP(TRUE, EXACT(Table2[[#This Row],[orig]], Table6[orig]), Table6[(H-reflection)])} -> R2 | X14: {=_xlfn.XLOOKUP(TRUE, EXACT(Table2[[#This Row],[H-reflection]], Table9[orig]), Table9[char])} -> J | Y14: {=_xlfn.XLOOKUP(TRUE, EXACT(Table2[[#This Row],[orig]], Table7[orig]), Table7[(S-reflection)])} -> R2 | Z14: {=_xlfn.XLOOKUP(TRUE, EXACT(Table2[[#This Row],[S-reflection]], Table9[orig]), Table9[char])} -> J
... A55: =Tables!E58 -> Y2 | B55: {=_xlfn.XLOOKUP(TRUE, EXACT(Table2[[#This Row],[orig]], Table9[orig]), Table9[char])} -> I | C55: {=_xlfn.XLOOKUP(TRUE, EXACT(Table2[[#This Row],[orig]], Table4[orig]), Table4[(X)])} -> Z2 | D55: {=_xlfn.XLOOKUP(TRUE, EXACT(Table2[[#This Row],[X]], Table9[orig]), Table9[char])} -> = | E55: {=_xlfn.XLOOKUP(TRUE, EXACT(C55, Table4[orig]), Table4[(X)])} -> Y2 | F55: {=_xlfn.XLOOKUP(TRUE, EXACT(Table2[[#This Row],[X2]], Table9[orig]), Table9[char])} -> I | G55: {=_xlfn.XLOOKUP(TRUE, EXACT(E55, Table4[orig]), Table4[(X)])} -> Z2 | H55: {=_xlfn.XLOOKUP(TRUE, EXACT(Table2[[#This Row],[X'']], Table9[orig]), Table9[char])} -> = | I55: {=_xlfn.XLOOKUP(TRUE, EXACT(A55, Table1[orig]), Table1[(Y)])} -> Y2 | J55: {=_xlfn.XLOOKUP(TRUE, EXACT(Table2[[#This Row],[Y]], Table9[orig]), Table9[char])} -> I | K55: {=_xlfn.XLOOKUP(TRUE, EXACT(I55, Table1[orig]), Table1[(Y)])} -> Y2 | L55: {=_xlfn.XLOOKUP(TRUE, EXACT(Table2[[#This Row],[Y2]], Table9[orig]), Table9[char])} -> I | M55: {=_xlfn.XLOOKUP(TRUE, EXACT(K55, Table1[orig]), Table1[(Y)])} -> Y2 | N55: {=_xlfn.XLOOKUP(TRUE, EXACT(Table2[[#This Row],[Y'']], Table9[orig]), Table9[char])} -> I | O55: {=_xlfn.XLOOKUP(TRUE, EXACT(Table2[[#This Row],[orig]], Table3[orig]), Table3[(Z)])} -> X2 | P55: {=_xlfn.XLOOKUP(TRUE, EXACT(Table2[[#This Row],[Z]], Table9[orig]), Table9[char])} -> P | Q55: {=_xlfn.XLOOKUP(TRUE, EXACT(O55, Table3[orig]), Table3[(Z)])} -> Y2 | R55: {=_xlfn.XLOOKUP(TRUE, EXACT(Table2[[#This Row],[Z2]], Table9[orig]), Table9[char])} -> I | S55: {=_xlfn.XLOOKUP(TRUE, EXACT(Q55, Table3[orig]), Table3[(Z)])} -> X2 | T55: {=_xlfn.XLOOKUP(TRUE, EXACT(Table2[[#This Row],[Z'']], Table9[orig]), Table9[char])} -> P | U55: {=_xlfn.XLOOKUP(TRUE, EXACT(Table2[[#This Row],[orig]], Table5[orig]), Table5[(T-reflection)])} -> Y2 | V55: {=_xlfn.XLOOKUP(TRUE, EXACT(Table2[[#This Row],[T-reflection]], Table9[orig]), Table9[char])} -> I | W55: {=_xlfn.XLOOKUP(TRUE, EXACT(Table2[[#This Row],[orig]], Table6[orig]), Table6[(H-reflection)])} -> Y2 | X55: {=_xlfn.XLOOKUP(TRUE, EXACT(Table2[[#This Row],[H-reflection]], Table9[orig]), Table9[char])} -> I | Y55: {=_xlfn.XLOOKUP(TRUE, EXACT(Table2[[#This Row],[orig]], Table7[orig]), Table7[(S-reflection)])} -> Y2 | Z55: {=_xlfn.XLOOKUP(TRUE, EXACT(Table2[[#This Row],[S-reflection]], Table9[orig]), Table9[char])} -> I
