Workbook

Sheet intermediate
B2: The lock password is "password" | F2: Still available for ascii chars: o, =, |
B4: orig | C4: (X) | E4: orig | F4: (Y) | H4: orig | I4: (Z) | K4: orig | L4: (T-reflection) | N4: orig | O4: (H-reflection) | Q4: orig | R4: (S-reflection)
B5: R | C5: R | E5: R | F5: F | H5: R | I5: D | K5: R | L5: L' | N5: R | O5: R' | Q5: R | R5: R'
B6: r | C6: r | E6: r | F6: f | H6: r | I6: d | K6: r | L6: l' | N6: r | O6: r' | Q6: r | R6: r'
B7: T | C7: T | E7: T | F7: S | H7: T | I7: H' | K7: T | L7: T | N7: T | O7: T' | Q7: T | R7: T'
B8: l | C8: l | E8: l | F8: b | H8: l | I8: u | K8: l | L8: r' | N8: l | O8: l' | Q8: l | R8: l'
B9: L | C9: L | E9: L | F9: B | H9: L | I9: U | K9: L | L9: R' | N9: L | O9: L' | Q9: L | R9: L'
B10: X | C10: X | E10: X | F10: Z | H10: X | I10: Y' | K10: X | L10: X | N10: X | O10: X' | Q10: X | R10: X'
B11: R' | C11: R' | E11: R' | F11: F' | H11: R' | I11: D' | K11: R' | L11: L | N11: R' | O11: R | Q11: R' | R11: R
B12: r' | C12: r' | E12: r' | F12: f' | H12: r' | I12: d' | K12: r' | L12: l | N12: r' | O12: r | Q12: r' | R12: r
B13: T' | C13: T' | E13: T' | F13: S' | H13: T' | I13: H | K13: T' | L13: T' | N13: T' | O13: T | Q13: T' | R13: T
B14: l' | C14: l' | E14: l' | F14: b' | H14: l' | I14: u' | K14: l' | L14: r | N14: l' | O14: l | Q14: l' | R14: l
B15: L' | C15: L' | E15: L' | F15: B' | H15: L' | I15: U' | K15: L' | L15: R | N15: L' | O15: L | Q15: L' | R15: L
... B58: Y2 | C58: Z2 | E58: Y2 | F58: Y2 | H58: Y2 | I58: X2 | K58: Y2 | L58: Y2 | N58: Y2 | O58: Y2 | Q58: Y2 | R58: Y2

Sheet Other Tables
B3: Both face turns whose complement has a given rotation | E3: - | F3: SeekCodes | L3: All Coros (Core Rotations) | S3: DO6 - multiple methods of identification | Y3: Mod 4 tracker
B4: Rotation | C4: Opposite Primary | D4: Opposite Secondary | F4: Face Turn Sought | G4: char | H4: opp Rotation | I4: SeekCode | L4: Coro | M4: Type | N4: Group | O4: thumb pivot | P4: U-F center | Q4: 180 swap | S4: Types | T4: Groups | U4: Thumbs | V4: U-F centers | W4: 180 swaps | Y4: X | Z4: Y | AA4: Z | AB4: RotationNum | AC4: CompRotationNum
B5: X | C5: R' | D5: L | F5: R | G5: {=_xlfn.XLOOKUP(TRUE, EXACT(Table12[[#This Row],[Face Turn Sought]], Table9[orig]), #REF!)} -> #REF! | H5: X' | I5: 2 | L5: X2 Y | M5: X2 Y | N5: Group 1 | O5: FR | P5: yellow-blue | Q5: PAPER | S5: X2 Y | T5: Group 1 | U5: FR | V5: yellow-blue | W5: PAPER | Y5: MyAlg | Z5: MyAlg | AA5: MyAlg | AB5: 0 | AC5: =MOD(4-Table14[[#This Row],[RotationNum]],4) -> 0
F6: r | G6: {=_xlfn.XLOOKUP(TRUE, EXACT(Table12[[#This Row],[Face Turn Sought]], Table9[orig]), #REF!)} -> #REF! | H6: X' | L6: Y' X2 | M6: X2 Y | N6: Group 1 | O6: FR | P6: yellow-blue | Q6: PAPER | S6: X2 Y' | T6: Group 2 | U6: FL | V6: yellow-green | W6: PAPER | Y6: X | Z6: Y | AA6: Z | AB6: 1 | AC6: =MOD(4-Table14[[#This Row],[RotationNum]],4) -> 3
L7: Z2 Y' | M7: X2 Y | N7: Group 1 | O7: FR | P7: yellow-blue | Q7: PAPER | S7: Y2 Z | T7: Group 3 | U7: UR | V7: blue-orange | W7: FIRE | Y7: R | AB7: 1 | AC7: =MOD(4-Table14[[#This Row],[RotationNum]],4) -> 3
F8: l | G8: {=_xlfn.XLOOKUP(TRUE, EXACT(Table12[[#This Row],[Face Turn Sought]], Table9[orig]), #REF!)} -> #REF! | H8: X | L8: Y Z2 | M8: X2 Y | N8: Group 1 | O8: FR | P8: yellow-blue | Q8: PAPER | S8: Y2 Z' | T8: Group 4 | U8: UL | V8: green-orange | W8: FIRE | Y8: r | AB8: 1 | AC8: =MOD(4-Table14[[#This Row],[RotationNum]],4) -> 3
F9: L | G9: {=_xlfn.XLOOKUP(TRUE, EXACT(Table12[[#This Row],[Face Turn Sought]], Table9[orig]), #REF!)} -> #REF! | H9: X | I9: 1 | L9: X X Y | M9: X2 Y | N9: Group 1 | O9: FR | P9: yellow-blue | Q9: PAPER | S9: Z2 X | T9: Group 5 | U9: UF | V9: red-white | W9: WATER | Y9: T | AB9: 1 | AC9: =MOD(4-Table14[[#This Row],[RotationNum]],4) -> 3
L10: X' X' Y | M10: X2 Y | N10: Group 1 | O10: FR | P10: yellow-blue | Q10: PAPER | S10: Z2 X' | T10: Group 6 | U10: UB | V10: orange-yellow | W10: WATER | Y10: M' | AB10: 1 | AC10: =MOD(4-Table14[[#This Row],[RotationNum]],4) -> 3
B11: X' | C11: R | D11: L' | F11: R' | G11: {=_xlfn.XLOOKUP(TRUE, EXACT(Table12[[#This Row],[Face Turn Sought]], Table9[orig]), #REF!)} -> #REF! | H11: X | I11: 1 | L11: Y' X X | M11: X2 Y | N11: Group 1 | O11: FR | P11: yellow-blue | Q11: PAPER | Y11: l' | AB11: 1 | AC11: =MOD(4-Table14[[#This Row],[RotationNum]],4) -> 3
F12: r' | G12: {=_xlfn.XLOOKUP(TRUE, EXACT(Table12[[#This Row],[Face Turn Sought]], Table9[orig]), #REF!)} -> #REF! | H12: X | L12: Y' X' X' | M12: X2 Y | N12: Group 1 | O12: FR | P12: yellow-blue | Q12: PAPER | Y12: L' | AB12: 1 | AC12: =MOD(4-Table14[[#This Row],[RotationNum]],4) -> 3
L13: Z Z Y' | M13: X2 Y | N13: Group 1 | O13: FR | P13: yellow-blue | Q13: PAPER | Y13: X2 | Z13: Y2 | AA13: Z2 | AB13: 2 | AC13: =MOD(4-Table14[[#This Row],[RotationNum]],4) -> 2
F14: l' | G14: {=_xlfn.XLOOKUP(TRUE, EXACT(Table12[[#This Row],[Face Turn Sought]], Table9[orig]), #REF!)} -> #REF! | H14: X' | L14: Z' Z' Y' | M14: X2 Y | N14: Group 1 | O14: FR | P14: yellow-blue | Q14: PAPER | Y14: R2 | AB14: 2 | AC14: =MOD(4-Table14[[#This Row],[RotationNum]],4) -> 2
F15: L' | G15: {=_xlfn.XLOOKUP(TRUE, EXACT(Table12[[#This Row],[Face Turn Sought]], Table9[orig]), #REF!)} -> #REF! | H15: X' | I15: 2 | L15: Y Z Z | M15: X2 Y | N15: Group 1 | O15: FR | P15: yellow-blue | Q15: PAPER | Y15: r2 | AB15: 2 | AC15: =MOD(4-Table14[[#This Row],[RotationNum]],4) -> 2
L16: Y Z' Z' | M16: X2 Y | N16: Group 1 | O16: FR | P16: yellow-blue | Q16: PAPER | Y16: T2 | AB16: 2 | AC16: =MOD(4-Table14[[#This Row],[RotationNum]],4) -> 2
B17: X2 | C17: R2 | D17: L2 | F17: R2 | G17: {=_xlfn.XLOOKUP(TRUE, EXACT(Table12[[#This Row],[Face Turn Sought]], Table9[orig]), #REF!)} -> #REF! | H17: X2 | I17: 3 | L17: X Z X | M17: X2 Y | N17: Group 1 | O17: FR | P17: yellow-blue | Q17: PAPER | Y17: M2 | AB17: 2 | AC17: =MOD(4-Table14[[#This Row],[RotationNum]],4) -> 2
F18: r2 | G18: {=_xlfn.XLOOKUP(TRUE, EXACT(Table12[[#This Row],[Face Turn Sought]], Table9[orig]), #REF!)} -> #REF! | H18: X2 | L18: X' Z' X' | M18: X2 Y | N18: Group 1 | O18: FR | P18: yellow-blue | Q18: PAPER | Y18: l2 | AB18: 2 | AC18: =MOD(4-Table14[[#This Row],[RotationNum]],4) -> 2
L19: Z X Z | M19: X2 Y | N19: Group 1 | O19: FR | P19: yellow-blue | Q19: PAPER | Y19: L2 | AB19: 2 | AC19: =MOD(4-Table14[[#This Row],[RotationNum]],4) -> 2
F20: l2 | G20: {=_xlfn.XLOOKUP(TRUE, EXACT(Table12[[#This Row],[Face Turn Sought]], Table9[orig]), #REF!)} -> #REF! | H20: X2 | L20: Z' X' Z' | M20: X2 Y | N20: Group 1 | O20: FR | P20: yellow-blue | Q20: PAPER | Y20: X' | Z20: Y' | AA20: Z' | AB20: 3 | AC20: =MOD(4-Table14[[#This Row],[RotationNum]],4) -> 1
F21: L2 | G21: {=_xlfn.XLOOKUP(TRUE, EXACT(Table12[[#This Row],[Face Turn Sought]], Table9[orig]), #REF!)} -> #REF! | H21: X2 | I21: 3 | L21: X Y Z | M21: X2 Y | N21: Group 1 | O21: FR | P21: yellow-blue | Q21: PAPER | Y21: R' | AB21: 3 | AC21: =MOD(4-Table14[[#This Row],[RotationNum]],4) -> 1
L22: Z' Y' X' | M22: X2 Y | N22: Group 1 | O22: FR | P22: yellow-blue | Q22: PAPER | Y22: r' | AB22: 3 | AC22: =MOD(4-Table14[[#This Row],[RotationNum]],4) -> 1
B23: Z | C23: F' | D23: B | F23: F | G23: {=_xlfn.XLOOKUP(TRUE, EXACT(Table12[[#This Row],[Face Turn Sought]], Table9[orig]), #REF!)} -> #REF! | H23: Z' | I23: 8 | L23: X' Y Z' | M23: X2 Y | N23: Group 1 | O23: FR | P23: yellow-blue | Q23: PAPER | Y23: T' | AB23: 3 | AC23: =MOD(4-Table14[[#This Row],[RotationNum]],4) -> 1
L24: Z Y' X | M24: X2 Y | N24: Group 1 | O24: FR | P24: yellow-blue | Q24: PAPER | Y24: M | AB24: 3 | AC24: =MOD(4-Table14[[#This Row],[RotationNum]],4) -> 1
L25: X2 Y' | M25: X2 Y' | N25: Group 2 | O25: FL | P25: yellow-green | Q25: PAPER | Y25: l | AB25: 3 | AC25: =MOD(4-Table14[[#This Row],[RotationNum]],4) -> 1
L26: Y X2 | M26: X2 Y' | N26: Group 2 | O26: FL | P26: yellow-green | Q26: PAPER | Y26: L | AB26: 3 | AC26: =MOD(4-Table14[[#This Row],[RotationNum]],4) -> 1
F27: B | G27: {=_xlfn.XLOOKUP(TRUE, EXACT(Table12[[#This Row],[Face Turn Sought]], Table9[orig]), #REF!)} -> #REF! | H27: Z | I27: 7 | L27: Z2 Y | M27: X2 Y' | N27: Group 2 | O27: FL | P27: yellow-green | Q27: PAPER
L28: Y' Z2 | M28: X2 Y' | N28: Group 2 | O28: FL | P28: yellow-green | Q28: PAPER
B29: Z' | C29: F | D29: B' | F29: F' | G29: {=_xlfn.XLOOKUP(TRUE, EXACT(Table12[[#This Row],[Face Turn Sought]], Table9[orig]), #REF!)} -> #REF! | H29: Z | I29: 7 | L29: X X Y' | M29: X2 Y' | N29: Group 2 | O29: FL | P29: yellow-green | Q29: PAPER
L30: X' X' Y' | M30: X2 Y' | N30: Group 2 | O30: FL | P30: yellow-green | Q30: PAPER
L31: Y X X | M31: X2 Y' | N31: Group 2 | O31: FL | P31: yellow-green | Q31: PAPER
L32: Y X' X' | M32: X2 Y' | N32: Group 2 | O32: FL | P32: yellow-green | Q32: PAPER
F33: B' | G33: {=_xlfn.XLOOKUP(TRUE, EXACT(Table12[[#This Row],[Face Turn Sought]], Table9[orig]), #REF!)} -> #REF! | H33: Z' | I33: 8 | L33: Z Z Y | M33: X2 Y' | N33: Group 2 | O33: FL | P33: yellow-green | Q33: PAPER
L34: Z' Z' Y | M34: X2 Y' | N34: Group 2 | O34: FL | P34: yellow-green | Q34: PAPER
B35: Z2 | C35: F2 | D35: B2 | F35: F2 | G35: {=_xlfn.XLOOKUP(TRUE, EXACT(Table12[[#This Row],[Face Turn Sought]], Table9[orig]), #REF!)} -> #REF! | H35: Z2 | I35: 9 | L35: Y' Z Z | M35: X2 Y' | N35: Group 2 | O35: FL | P35: yellow-green | Q35: PAPER
L36: Y' Z' Z' | M36: X2 Y' | N36: Group 2 | O36: FL | P36: yellow-green | Q36: PAPER
L37: X Z' X | M37: X2 Y' | N37: Group 2 | O37: FL | P37: yellow-green | Q37: PAPER
L38: X' Z X' | M38: X2 Y' | N38: Group 2 | O38: FL | P38: yellow-green | Q38: PAPER
F39: B2 | G39: {=_xlfn.XLOOKUP(TRUE, EXACT(Table12[[#This Row],[Face Turn Sought]], Table9[orig]), #REF!)} -> #REF! | H39: Z2 | I39: 9 | L39: Z X' Z | M39: X2 Y' | N39: Group 2 | O39: FL | P39: yellow-green | Q39: PAPER
L40: Z' X Z' | M40: X2 Y' | N40: Group 2 | O40: FL | P40: yellow-green | Q40: PAPER
B41: Y | C41: U' | D41: D | F41: U | G41: {=_xlfn.XLOOKUP(TRUE, EXACT(Table12[[#This Row],[Face Turn Sought]], Table9[orig]), #REF!)} -> #REF! | H41: Y' | I41: 5 | L41: X Y' Z' | M41: X2 Y' | N41: Group 2 | O41: FL | P41: yellow-green | Q41: PAPER
L42: Z Y X' | M42: X2 Y' | N42: Group 2 | O42: FL | P42: yellow-green | Q42: PAPER
...

Sheet basics
A1: orig | B1: inverse | C1: Complement | D1: Rotation Direction
A2: R | B2: R' | C2: l | D2: X
A3: r | B3: r' | C3: L | D3: X
A4: T | B4: T' | C4: R'L | D4: X
A5: l | B5: l' | C5: R | D5: X'
A6: L | B6: L' | C6: r | D6: X'
A7: X | B7: X' | C7: 0 | D7: X
A8: R' | B8: R | C8: l' | D8: X'
A9: r' | B9: r | C9: L' | D9: X'
A10: T' | B10: T | C10: RL' | D10: X'
A11: l' | B11: l | C11: R' | D11: X
A12: L' | B12: L | C12: r' | D12: X
A13: X' | B13: X | C13: 0 | D13: X'
A14: R2 | B14: R2 | C14: l2 | D14: X2
A15: r2 | B15: r2 | C15: L2 | D15: X2
A16: T2 | B16: T2 | C16: R2L2 | D16: X2
A17: l2 | B17: l2 | C17: R2 | D17: X2
A18: L2 | B18: L2 | C18: r2 | D18: X2
A19: X2 | B19: X2 | C19: 0 | D19: X2
A20: F | B20: F' | C20: b | D20: Z
A21: f | B21: f' | C21: B | D21: Z
A22: S | B22: S' | C22: F'B | D22: Z
A23: b | B23: b' | C23: F | D23: Z'
A24: B | B24: B' | C24: f | D24: Z'
A25: Z | B25: Z' | C25: 0 | D25: Z
A26: F' | B26: F | C26: b' | D26: Z'
A27: f' | B27: f | C27: B' | D27: Z'
A28: S' | B28: S | C28: FB' | D28: Z'
A29: b' | B29: b | C29: F' | D29: Z
A30: B' | B30: B | C30: f' | D30: Z
A31: Z' | B31: Z | C31: 0 | D31: Z'
A32: F2 | B32: F2 | C32: b2 | D32: Z2
A33: f2 | B33: f2 | C33: B2 | D33: Z2
A34: S2 | B34: S2 | C34: F2B2 | D34: Z2
A35: b2 | B35: b2 | C35: F2 | D35: Z2
A36: B2 | B36: B2 | C36: f2 | D36: Z2
A37: Z2 | B37: Z2 | C37: 0 | D37: Z2
A38: U | B38: U' | C38: d | D38: Y
A39: u | B39: u' | C39: D | D39: Y
A40: H | B40: H' | C40: U'D | D40: Y
...

Sheet transformations
A1: orig | B1: AX-->XB | C1: AX2-->X2B | D1: AX'-->X'B | E1: AY-->YB | F1: AY2-->Y2B | G1: AY'-->Y'B | H1: AZ-->ZB | I1: AZ2-->Z2B | J1: AZ'-->Z'B | K1: T-reflection | L1: H-reflection | M1: S-reflection
A2: =intermediate!E5 -> R | B2: {=_xlfn.XLOOKUP(TRUE, EXACT(Table2[[#This Row],[orig]], Table4[orig]), Table4[(X)])} -> R | C2: {=_xlfn.XLOOKUP(TRUE, EXACT(B2, Table4[orig]), Table4[(X)])} -> R | D2: {=_xlfn.XLOOKUP(TRUE, EXACT(C2, Table4[orig]), Table4[(X)])} -> R | E2: {=_xlfn.XLOOKUP(TRUE, EXACT(Table2[orig], Table1[orig]), Table1[(Y)])} -> F | F2: {=_xlfn.XLOOKUP(TRUE, EXACT(E2, Table1[orig]), Table1[(Y)])} -> L | G2: {=_xlfn.XLOOKUP(TRUE, EXACT(F2, Table1[orig]), Table1[(Y)])} -> B | H2: {=_xlfn.XLOOKUP(TRUE, EXACT(Table2[[#This Row],[orig]], Table3[orig]), Table3[(Z)])} -> D | I2: {=_xlfn.XLOOKUP(TRUE, EXACT(H2, Table3[orig]), Table3[(Z)])} -> L | J2: {=_xlfn.XLOOKUP(TRUE, EXACT(I2, Table3[orig]), Table3[(Z)])} -> U | K2: {=_xlfn.XLOOKUP(TRUE, EXACT(Table2[[#This Row],[orig]], Table5[orig]), Table5[(T-reflection)])} -> L' | L2: {=_xlfn.XLOOKUP(TRUE, EXACT(Table2[[#This Row],[orig]], Table6[orig]), Table6[(H-reflection)])} -> R' | M2: {=_xlfn.XLOOKUP(TRUE, EXACT(Table2[[#This Row],[orig]], Table7[orig]), Table7[(S-reflection)])} -> R'
A3: =intermediate!E6 -> r | B3: {=_xlfn.XLOOKUP(TRUE, EXACT(Table2[[#This Row],[orig]], Table4[orig]), Table4[(X)])} -> r | C3: {=_xlfn.XLOOKUP(TRUE, EXACT(B3, Table4[orig]), Table4[(X)])} -> r | D3: {=_xlfn.XLOOKUP(TRUE, EXACT(C3, Table4[orig]), Table4[(X)])} -> r | E3: {=_xlfn.XLOOKUP(TRUE, EXACT(A3, Table1[orig]), Table1[(Y)])} -> f | F3: {=_xlfn.XLOOKUP(TRUE, EXACT(E3, Table1[orig]), Table1[(Y)])} -> l | G3: {=_xlfn.XLOOKUP(TRUE, EXACT(F3, Table1[orig]), Table1[(Y)])} -> b | H3: {=_xlfn.XLOOKUP(TRUE, EXACT(Table2[[#This Row],[orig]], Table3[orig]), Table3[(Z)])} -> d | I3: {=_xlfn.XLOOKUP(TRUE, EXACT(H3, Table3[orig]), Table3[(Z)])} -> l | J3: {=_xlfn.XLOOKUP(TRUE, EXACT(I3, Table3[orig]), Table3[(Z)])} -> u | K3: {=_xlfn.XLOOKUP(TRUE, EXACT(Table2[[#This Row],[orig]], Table5[orig]), Table5[(T-reflection)])} -> l' | L3: {=_xlfn.XLOOKUP(TRUE, EXACT(Table2[[#This Row],[orig]], Table6[orig]), Table6[(H-reflection)])} -> r' | M3: {=_xlfn.XLOOKUP(TRUE, EXACT(Table2[[#This Row],[orig]], Table7[orig]), Table7[(S-reflection)])} -> r'
A4: =intermediate!E7 -> T | B4: {=_xlfn.XLOOKUP(TRUE, EXACT(Table2[[#This Row],[orig]], Table4[orig]), Table4[(X)])} -> T | C4: {=_xlfn.XLOOKUP(TRUE, EXACT(B4, Table4[orig]), Table4[(X)])} -> T | D4: {=_xlfn.XLOOKUP(TRUE, EXACT(C4, Table4[orig]), Table4[(X)])} -> T | E4: {=_xlfn.XLOOKUP(TRUE, EXACT(A4, Table1[orig]), Table1[(Y)])} -> S | F4: {=_xlfn.XLOOKUP(TRUE, EXACT(E4, Table1[orig]), Table1[(Y)])} -> T' | G4: {=_xlfn.XLOOKUP(TRUE, EXACT(F4, Table1[orig]), Table1[(Y)])} -> S' | H4: {=_xlfn.XLOOKUP(TRUE, EXACT(Table2[[#This Row],[orig]], Table3[orig]), Table3[(Z)])} -> H' | I4: {=_xlfn.XLOOKUP(TRUE, EXACT(H4, Table3[orig]), Table3[(Z)])} -> T' | J4: {=_xlfn.XLOOKUP(TRUE, EXACT(I4, Table3[orig]), Table3[(Z)])} -> H | K4: {=_xlfn.XLOOKUP(TRUE, EXACT(Table2[[#This Row],[orig]], Table5[orig]), Table5[(T-reflection)])} -> T | L4: {=_xlfn.XLOOKUP(TRUE, EXACT(Table2[[#This Row],[orig]], Table6[orig]), Table6[(H-reflection)])} -> T' | M4: {=_xlfn.XLOOKUP(TRUE, EXACT(Table2[[#This Row],[orig]], Table7[orig]), Table7[(S-reflection)])} -> T'
A5: =intermediate!E8 -> l | B5: {=_xlfn.XLOOKUP(TRUE, EXACT(Table2[[#This Row],[orig]], Table4[orig]), Table4[(X)])} -> l | C5: {=_xlfn.XLOOKUP(TRUE, EXACT(B5, Table4[orig]), Table4[(X)])} -> l | D5: {=_xlfn.XLOOKUP(TRUE, EXACT(C5, Table4[orig]), Table4[(X)])} -> l | E5: {=_xlfn.XLOOKUP(TRUE, EXACT(A5, Table1[orig]), Table1[(Y)])} -> b | F5: {=_xlfn.XLOOKUP(TRUE, EXACT(E5, Table1[orig]), Table1[(Y)])} -> r | G5: {=_xlfn.XLOOKUP(TRUE, EXACT(F5, Table1[orig]), Table1[(Y)])} -> f | H5: {=_xlfn.XLOOKUP(TRUE, EXACT(Table2[[#This Row],[orig]], Table3[orig]), Table3[(Z)])} -> u | I5: {=_xlfn.XLOOKUP(TRUE, EXACT(H5, Table3[orig]), Table3[(Z)])} -> r | J5: {=_xlfn.XLOOKUP(TRUE, EXACT(I5, Table3[orig]), Table3[(Z)])} -> d | K5: {=_xlfn.XLOOKUP(TRUE, EXACT(Table2[[#This Row],[orig]], Table5[orig]), Table5[(T-reflection)])} -> r' | L5: {=_xlfn.XLOOKUP(TRUE, EXACT(Table2[[#This Row],[orig]], Table6[orig]), Table6[(H-reflection)])} -> l' | M5: {=_xlfn.XLOOKUP(TRUE, EXACT(Table2[[#This Row],[orig]], Table7[orig]), Table7[(S-reflection)])} -> l'
A6: =intermediate!E9 -> L | B6: {=_xlfn.XLOOKUP(TRUE, EXACT(Table2[[#This Row],[orig]], Table4[orig]), Table4[(X)])} -> L | C6: {=_xlfn.XLOOKUP(TRUE, EXACT(B6, Table4[orig]), Table4[(X)])} -> L | D6: {=_xlfn.XLOOKUP(TRUE, EXACT(C6, Table4[orig]), Table4[(X)])} -> L | E6: {=_xlfn.XLOOKUP(TRUE, EXACT(A6, Table1[orig]), Table1[(Y)])} -> B | F6: {=_xlfn.XLOOKUP(TRUE, EXACT(E6, Table1[orig]), Table1[(Y)])} -> R | G6: {=_xlfn.XLOOKUP(TRUE, EXACT(F6, Table1[orig]), Table1[(Y)])} -> F | H6: {=_xlfn.XLOOKUP(TRUE, EXACT(Table2[[#This Row],[orig]], Table3[orig]), Table3[(Z)])} -> U | I6: {=_xlfn.XLOOKUP(TRUE, EXACT(H6, Table3[orig]), Table3[(Z)])} -> R | J6: {=_xlfn.XLOOKUP(TRUE, EXACT(I6, Table3[orig]), Table3[(Z)])} -> D | K6: {=_xlfn.XLOOKUP(TRUE, EXACT(Table2[[#This Row],[orig]], Table5[orig]), Table5[(T-reflection)])} -> R' | L6: {=_xlfn.XLOOKUP(TRUE, EXACT(Table2[[#This Row],[orig]], Table6[orig]), Table6[(H-reflection)])} -> L' | M6: {=_xlfn.XLOOKUP(TRUE, EXACT(Table2[[#This Row],[orig]], Table7[orig]), Table7[(S-reflection)])} -> L'
A7: =intermediate!E10 -> X | B7: {=_xlfn.XLOOKUP(TRUE, EXACT(Table2[[#This Row],[orig]], Table4[orig]), Table4[(X)])} -> X | C7: {=_xlfn.XLOOKUP(TRUE, EXACT(B7, Table4[orig]), Table4[(X)])} -> X | D7: {=_xlfn.XLOOKUP(TRUE, EXACT(C7, Table4[orig]), Table4[(X)])} -> X | E7: {=_xlfn.XLOOKUP(TRUE, EXACT(A7, Table1[orig]), Table1[(Y)])} -> Z | F7: {=_xlfn.XLOOKUP(TRUE, EXACT(E7, Table1[orig]), Table1[(Y)])} -> X' | G7: {=_xlfn.XLOOKUP(TRUE, EXACT(F7, Table1[orig]), Table1[(Y)])} -> Z' | H7: {=_xlfn.XLOOKUP(TRUE, EXACT(Table2[[#This Row],[orig]], Table3[orig]), Table3[(Z)])} -> Y' | I7: {=_xlfn.XLOOKUP(TRUE, EXACT(H7, Table3[orig]), Table3[(Z)])} -> X' | J7: {=_xlfn.XLOOKUP(TRUE, EXACT(I7, Table3[orig]), Table3[(Z)])} -> Y | K7: {=_xlfn.XLOOKUP(TRUE, EXACT(Table2[[#This Row],[orig]], Table5[orig]), Table5[(T-reflection)])} -> X | L7: {=_xlfn.XLOOKUP(TRUE, EXACT(Table2[[#This Row],[orig]], Table6[orig]), Table6[(H-reflection)])} -> X' | M7: {=_xlfn.XLOOKUP(TRUE, EXACT(Table2[[#This Row],[orig]], Table7[orig]), Table7[(S-reflection)])} -> X'
A8: =intermediate!E11 -> R' | B8: {=_xlfn.XLOOKUP(TRUE, EXACT(Table2[[#This Row],[orig]], Table4[orig]), Table4[(X)])} -> R' | C8: {=_xlfn.XLOOKUP(TRUE, EXACT(B8, Table4[orig]), Table4[(X)])} -> R' | D8: {=_xlfn.XLOOKUP(TRUE, EXACT(C8, Table4[orig]), Table4[(X)])} -> R' | E8: {=_xlfn.XLOOKUP(TRUE, EXACT(A8, Table1[orig]), Table1[(Y)])} -> F' | F8: {=_xlfn.XLOOKUP(TRUE, EXACT(E8, Table1[orig]), Table1[(Y)])} -> L' | G8: {=_xlfn.XLOOKUP(TRUE, EXACT(F8, Table1[orig]), Table1[(Y)])} -> B' | H8: {=_xlfn.XLOOKUP(TRUE, EXACT(Table2[[#This Row],[orig]], Table3[orig]), Table3[(Z)])} -> D' | I8: {=_xlfn.XLOOKUP(TRUE, EXACT(H8, Table3[orig]), Table3[(Z)])} -> L' | J8: {=_xlfn.XLOOKUP(TRUE, EXACT(I8, Table3[orig]), Table3[(Z)])} -> U' | K8: {=_xlfn.XLOOKUP(TRUE, EXACT(Table2[[#This Row],[orig]], Table5[orig]), Table5[(T-reflection)])} -> L | L8: {=_xlfn.XLOOKUP(TRUE, EXACT(Table2[[#This Row],[orig]], Table6[orig]), Table6[(H-reflection)])} -> R | M8: {=_xlfn.XLOOKUP(TRUE, EXACT(Table2[[#This Row],[orig]], Table7[orig]), Table7[(S-reflection)])} -> R
A9: =intermediate!E12 -> r' | B9: {=_xlfn.XLOOKUP(TRUE, EXACT(Table2[[#This Row],[orig]], Table4[orig]), Table4[(X)])} -> r' | C9: {=_xlfn.XLOOKUP(TRUE, EXACT(B9, Table4[orig]), Table4[(X)])} -> r' | D9: {=_xlfn.XLOOKUP(TRUE, EXACT(C9, Table4[orig]), Table4[(X)])} -> r' | E9: {=_xlfn.XLOOKUP(TRUE, EXACT(A9, Table1[orig]), Table1[(Y)])} -> f' | F9: {=_xlfn.XLOOKUP(TRUE, EXACT(E9, Table1[orig]), Table1[(Y)])} -> l' | G9: {=_xlfn.XLOOKUP(TRUE, EXACT(F9, Table1[orig]), Table1[(Y)])} -> b' | H9: {=_xlfn.XLOOKUP(TRUE, EXACT(Table2[[#This Row],[orig]], Table3[orig]), Table3[(Z)])} -> d' | I9: {=_xlfn.XLOOKUP(TRUE, EXACT(H9, Table3[orig]), Table3[(Z)])} -> l' | J9: {=_xlfn.XLOOKUP(TRUE, EXACT(I9, Table3[orig]), Table3[(Z)])} -> u' | K9: {=_xlfn.XLOOKUP(TRUE, EXACT(Table2[[#This Row],[orig]], Table5[orig]), Table5[(T-reflection)])} -> l | L9: {=_xlfn.XLOOKUP(TRUE, EXACT(Table2[[#This Row],[orig]], Table6[orig]), Table6[(H-reflection)])} -> r | M9: {=_xlfn.XLOOKUP(TRUE, EXACT(Table2[[#This Row],[orig]], Table7[orig]), Table7[(S-reflection)])} -> r
A10: =intermediate!E13 -> T' | B10: {=_xlfn.XLOOKUP(TRUE, EXACT(Table2[[#This Row],[orig]], Table4[orig]), Table4[(X)])} -> T' | C10: {=_xlfn.XLOOKUP(TRUE, EXACT(B10, Table4[orig]), Table4[(X)])} -> T' | D10: {=_xlfn.XLOOKUP(TRUE, EXACT(C10, Table4[orig]), Table4[(X)])} -> T' | E10: {=_xlfn.XLOOKUP(TRUE, EXACT(A10, Table1[orig]), Table1[(Y)])} -> S' | F10: {=_xlfn.XLOOKUP(TRUE, EXACT(E10, Table1[orig]), Table1[(Y)])} -> T | G10: {=_xlfn.XLOOKUP(TRUE, EXACT(F10, Table1[orig]), Table1[(Y)])} -> S | H10: {=_xlfn.XLOOKUP(TRUE, EXACT(Table2[[#This Row],[orig]], Table3[orig]), Table3[(Z)])} -> H | I10: {=_xlfn.XLOOKUP(TRUE, EXACT(H10, Table3[orig]), Table3[(Z)])} -> T | J10: {=_xlfn.XLOOKUP(TRUE, EXACT(I10, Table3[orig]), Table3[(Z)])} -> H' | K10: {=_xlfn.XLOOKUP(TRUE, EXACT(Table2[[#This Row],[orig]], Table5[orig]), Table5[(T-reflection)])} -> T' | L10: {=_xlfn.XLOOKUP(TRUE, EXACT(Table2[[#This Row],[orig]], Table6[orig]), Table6[(H-reflection)])} -> T | M10: {=_xlfn.XLOOKUP(TRUE, EXACT(Table2[[#This Row],[orig]], Table7[orig]), Table7[(S-reflection)])} -> T
A11: =intermediate!E14 -> l' | B11: {=_xlfn.XLOOKUP(TRUE, EXACT(Table2[[#This Row],[orig]], Table4[orig]), Table4[(X)])} -> l' | C11: {=_xlfn.XLOOKUP(TRUE, EXACT(B11, Table4[orig]), Table4[(X)])} -> l' | D11: {=_xlfn.XLOOKUP(TRUE, EXACT(C11, Table4[orig]), Table4[(X)])} -> l' | E11: {=_xlfn.XLOOKUP(TRUE, EXACT(A11, Table1[orig]), Table1[(Y)])} -> b' | F11: {=_xlfn.XLOOKUP(TRUE, EXACT(E11, Table1[orig]), Table1[(Y)])} -> r' | G11: {=_xlfn.XLOOKUP(TRUE, EXACT(F11, Table1[orig]), Table1[(Y)])} -> f' | H11: {=_xlfn.XLOOKUP(TRUE, EXACT(Table2[[#This Row],[orig]], Table3[orig]), Table3[(Z)])} -> u' | I11: {=_xlfn.XLOOKUP(TRUE, EXACT(H11, Table3[orig]), Table3[(Z)])} -> r' | J11: {=_xlfn.XLOOKUP(TRUE, EXACT(I11, Table3[orig]), Table3[(Z)])} -> d' | K11: {=_xlfn.XLOOKUP(TRUE, EXACT(Table2[[#This Row],[orig]], Table5[orig]), Table5[(T-reflection)])} -> r | L11: {=_xlfn.XLOOKUP(TRUE, EXACT(Table2[[#This Row],[orig]], Table6[orig]), Table6[(H-reflection)])} -> l | M11: {=_xlfn.XLOOKUP(TRUE, EXACT(Table2[[#This Row],[orig]], Table7[orig]), Table7[(S-reflection)])} -> l
A12: =intermediate!E15 -> L' | B12: {=_xlfn.XLOOKUP(TRUE, EXACT(Table2[[#This Row],[orig]], Table4[orig]), Table4[(X)])} -> L' | C12: {=_xlfn.XLOOKUP(TRUE, EXACT(B12, Table4[orig]), Table4[(X)])} -> L' | D12: {=_xlfn.XLOOKUP(TRUE, EXACT(C12, Table4[orig]), Table4[(X)])} -> L' | E12: {=_xlfn.XLOOKUP(TRUE, EXACT(A12, Table1[orig]), Table1[(Y)])} -> B' | F12: {=_xlfn.XLOOKUP(TRUE, EXACT(E12, Table1[orig]), Table1[(Y)])} -> R' | G12: {=_xlfn.XLOOKUP(TRUE, EXACT(F12, Table1[orig]), Table1[(Y)])} -> F' | H12: {=_xlfn.XLOOKUP(TRUE, EXACT(Table2[[#This Row],[orig]], Table3[orig]), Table3[(Z)])} -> U' | I12: {=_xlfn.XLOOKUP(TRUE, EXACT(H12, Table3[orig]), Table3[(Z)])} -> R' | J12: {=_xlfn.XLOOKUP(TRUE, EXACT(I12, Table3[orig]), Table3[(Z)])} -> D' | K12: {=_xlfn.XLOOKUP(TRUE, EXACT(Table2[[#This Row],[orig]], Table5[orig]), Table5[(T-reflection)])} -> R | L12: {=_xlfn.XLOOKUP(TRUE, EXACT(Table2[[#This Row],[orig]], Table6[orig]), Table6[(H-reflection)])} -> L | M12: {=_xlfn.XLOOKUP(TRUE, EXACT(Table2[[#This Row],[orig]], Table7[orig]), Table7[(S-reflection)])} -> L
A13: =intermediate!E16 -> X' | B13: {=_xlfn.XLOOKUP(TRUE, EXACT(Table2[[#This Row],[orig]], Table4[orig]), Table4[(X)])} -> X' | C13: {=_xlfn.XLOOKUP(TRUE, EXACT(B13, Table4[orig]), Table4[(X)])} -> X' | D13: {=_xlfn.XLOOKUP(TRUE, EXACT(C13, Table4[orig]), Table4[(X)])} -> X' | E13: {=_xlfn.XLOOKUP(TRUE, EXACT(A13, Table1[orig]), Table1[(Y)])} -> Z' | F13: {=_xlfn.XLOOKUP(TRUE, EXACT(E13, Table1[orig]), Table1[(Y)])} -> X | G13: {=_xlfn.XLOOKUP(TRUE, EXACT(F13, Table1[orig]), Table1[(Y)])} -> Z | H13: {=_xlfn.XLOOKUP(TRUE, EXACT(Table2[[#This Row],[orig]], Table3[orig]), Table3[(Z)])} -> Y | I13: {=_xlfn.XLOOKUP(TRUE, EXACT(H13, Table3[orig]), Table3[(Z)])} -> X | J13: {=_xlfn.XLOOKUP(TRUE, EXACT(I13, Table3[orig]), Table3[(Z)])} -> Y' | K13: {=_xlfn.XLOOKUP(TRUE, EXACT(Table2[[#This Row],[orig]], Table5[orig]), Table5[(T-reflection)])} -> X' | L13: {=_xlfn.XLOOKUP(TRUE, EXACT(Table2[[#This Row],[orig]], Table6[orig]), Table6[(H-reflection)])} -> X | M13: {=_xlfn.XLOOKUP(TRUE, EXACT(Table2[[#This Row],[orig]], Table7[orig]), Table7[(S-reflection)])} -> X
A14: =intermediate!E17 -> R2 | B14: {=_xlfn.XLOOKUP(TRUE, EXACT(Table2[[#This Row],[orig]], Table4[orig]), Table4[(X)])} -> R2 | C14: {=_xlfn.XLOOKUP(TRUE, EXACT(B14, Table4[orig]), Table4[(X)])} -> R2 | D14: {=_xlfn.XLOOKUP(TRUE, EXACT(C14, Table4[orig]), Table4[(X)])} -> R2 | E14: {=_xlfn.XLOOKUP(TRUE, EXACT(A14, Table1[orig]), Table1[(Y)])} -> F2 | F14: {=_xlfn.XLOOKUP(TRUE, EXACT(E14, Table1[orig]), Table1[(Y)])} -> L2 | G14: {=_xlfn.XLOOKUP(TRUE, EXACT(F14, Table1[orig]), Table1[(Y)])} -> B2 | H14: {=_xlfn.XLOOKUP(TRUE, EXACT(Table2[[#This Row],[orig]], Table3[orig]), Table3[(Z)])} -> D2 | I14: {=_xlfn.XLOOKUP(TRUE, EXACT(H14, Table3[orig]), Table3[(Z)])} -> L2 | J14: {=_xlfn.XLOOKUP(TRUE, EXACT(I14, Table3[orig]), Table3[(Z)])} -> U2 | K14: {=_xlfn.XLOOKUP(TRUE, EXACT(Table2[[#This Row],[orig]], Table5[orig]), Table5[(T-reflection)])} -> L2 | L14: {=_xlfn.XLOOKUP(TRUE, EXACT(Table2[[#This Row],[orig]], Table6[orig]), Table6[(H-reflection)])} -> R2 | M14: {=_xlfn.XLOOKUP(TRUE, EXACT(Table2[[#This Row],[orig]], Table7[orig]), Table7[(S-reflection)])} -> R2
... A55: =intermediate!E58 -> Y2 | B55: {=_xlfn.XLOOKUP(TRUE, EXACT(Table2[[#This Row],[orig]], Table4[orig]), Table4[(X)])} -> Z2 | C55: {=_xlfn.XLOOKUP(TRUE, EXACT(B55, Table4[orig]), Table4[(X)])} -> Y2 | D55: {=_xlfn.XLOOKUP(TRUE, EXACT(C55, Table4[orig]), Table4[(X)])} -> Z2 | E55: {=_xlfn.XLOOKUP(TRUE, EXACT(A55, Table1[orig]), Table1[(Y)])} -> Y2 | F55: {=_xlfn.XLOOKUP(TRUE, EXACT(E55, Table1[orig]), Table1[(Y)])} -> Y2 | G55: {=_xlfn.XLOOKUP(TRUE, EXACT(F55, Table1[orig]), Table1[(Y)])} -> Y2 | H55: {=_xlfn.XLOOKUP(TRUE, EXACT(Table2[[#This Row],[orig]], Table3[orig]), Table3[(Z)])} -> X2 | I55: {=_xlfn.XLOOKUP(TRUE, EXACT(H55, Table3[orig]), Table3[(Z)])} -> Y2 | J55: {=_xlfn.XLOOKUP(TRUE, EXACT(I55, Table3[orig]), Table3[(Z)])} -> X2 | K55: {=_xlfn.XLOOKUP(TRUE, EXACT(Table2[[#This Row],[orig]], Table5[orig]), Table5[(T-reflection)])} -> Y2 | L55: {=_xlfn.XLOOKUP(TRUE, EXACT(Table2[[#This Row],[orig]], Table6[orig]), Table6[(H-reflection)])} -> Y2 | M55: {=_xlfn.XLOOKUP(TRUE, EXACT(Table2[[#This Row],[orig]], Table7[orig]), Table7[(S-reflection)])} -> Y2
